Workbook

Sheet 🎯倚盟今日排行
A1: 🎯 倚盟今日排行 - 即時追蹤業績排名
A2: 📅 今日日期： | B2: =TODAY()-1 -> 46290 | D2: ⏰ 剩餘天數： | E2: =EOMONTH(TODAY(),0)-TODAY()-1 -> 3 | G2: 📊 業績週期： | H2: 9月上半場 8/30-9/13 | J2: 📊 業績週期： | K2: 9月下半場9/14-9/28
A4: 🏆 總獎金 TOP 5 排行榜 | H4: 🏪 各店業績統計
A5: 排名 | B5: 姓名 | C5: 店點 | D5: 總獎金 | E5: 等級 | F5: 進度條 | H5: 店點 | I5: 人數 | J5: AQ累計 | K5: RT累計 | L5: 手機案累計 | M5: 總獎金 | N5: 平均獎金
A6: =ROW(A1) -> 1 | B6: =INDEX(【你的全部獎金】!$B$7:$B$26,MATCH($D6,【你的全部獎金】!$Q$7:$Q$26,0)) -> 黃庭鈞 | C6: =INDEX(【你的全部獎金】!$A$7:$A$26,MATCH($D6,【你的全部獎金】!$Q$7:$Q$26,0)) -> 區督導 | D6: =LARGE(【你的全部獎金】!$Q$7:$Q$26,ROW(A1)) -> 45886.27 | E6: =IF(D6>=14000,"🏆全壘打",IF(D6>=10000,"⭐明星",IF(D6>=7000,"💪優秀",IF(D6>=4000,"✅合格","📈加油")))) -> 🏆全壘打 | F6: =REPT("█",MIN(20,INT(D6/1000)))&REPT("░",20-MIN(20,INT(D6/1000))) -> ████████████████████ | H6: 鼎山店 | I6: 4 | J6: =SUMIF($H33:$H37,$H6,$K33:$K37) -> 98.5 | K6: =SUMIF($H$42:$H$46,$H6,$K$42:$K$46) -> 520.95 | L6: 65 | M6: =SUMIF(【你的全部獎金】!$A$7:$A$26,$H6,【你的全部獎金】!$Q$7:$Q$26) -> 71025.806 | N6: =IFERROR(M6/I6,0) -> 17756.451
A7: =ROW(A2) -> 2 | B7: =INDEX(【你的全部獎金】!$B$7:$B$26,MATCH($D7,【你的全部獎金】!$Q$7:$Q$26,0)) -> 黃傑稜 | C7: =INDEX(【你的全部獎金】!$A$7:$A$26,MATCH($D7,【你的全部獎金】!$Q$7:$Q$26,0)) -> 仁雄店 | D7: =LARGE(【你的全部獎金】!$Q$7:$Q$26,ROW(A2)) -> 45734.168 | E7: =IF(D7>=14000,"🏆全壘打",IF(D7>=10000,"⭐明星",IF(D7>=7000,"💪優秀",IF(D7>=4000,"✅合格","📈加油")))) -> 🏆全壘打 | F7: =REPT("█",MIN(20,INT(D7/1000)))&REPT("░",20-MIN(20,INT(D7/1000))) -> ████████████████████ | H7: 陽明店 | I7: 3 | J7: =SUMIF($H34:$H38,$H7,$K34:$K38) -> 65 | K7: =SUMIF($H$42:$H$46,$H7,$K$42:$K$46) -> 380.45 | L7: 45 | M7: =SUMIF(【你的全部獎金】!$A$7:$A$26,$H7,【你的全部獎金】!$Q$7:$Q$26) -> 53536.551 | N7: =IFERROR(M7/I7,0) -> 17845.517
A8: =ROW(A3) -> 3 | B8: =INDEX(【你的全部獎金】!$B$7:$B$26,MATCH($D8,【你的全部獎金】!$Q$7:$Q$26,0)) -> 陳宛姍 | C8: =INDEX(【你的全部獎金】!$A$7:$A$26,MATCH($D8,【你的全部獎金】!$Q$7:$Q$26,0)) -> 凱旋店 | D8: =LARGE(【你的全部獎金】!$Q$7:$Q$26,ROW(A3)) -> 45290.483 | E8: =IF(D8>=14000,"🏆全壘打",IF(D8>=10000,"⭐明星",IF(D8>=7000,"💪優秀",IF(D8>=4000,"✅合格","📈加油")))) -> 🏆全壘打 | F8: =REPT("█",MIN(20,INT(D8/1000)))&REPT("░",20-MIN(20,INT(D8/1000))) -> ████████████████████ | H8: 後昌店 | I8: 3 | J8: =SUMIF($H35:$H39,$H8,$K35:$K39) -> 41 | K8: =SUMIF($H$42:$H$46,$H8,$K$42:$K$46) -> 468.7 | L8: 53 | M8: =SUMIF(【你的全部獎金】!$A$7:$A$26,$H8,【你的全部獎金】!$Q$7:$Q$26) -> 68501.395 | N8: =IFERROR(M8/I8,0) -> 22833.798
A9: =ROW(A4) -> 4 | B9: =INDEX(【你的全部獎金】!$B$7:$B$26,MATCH($D9,【你的全部獎金】!$Q$7:$Q$26,0)) -> 黃閔聖 | C9: =INDEX(【你的全部獎金】!$A$7:$A$26,MATCH($D9,【你的全部獎金】!$Q$7:$Q$26,0)) -> 後昌店 | D9: =LARGE(【你的全部獎金】!$Q$7:$Q$26,ROW(A4)) -> 42270.014 | E9: =IF(D9>=14000,"🏆全壘打",IF(D9>=10000,"⭐明星",IF(D9>=7000,"💪優秀",IF(D9>=4000,"✅合格","📈加油")))) -> 🏆全壘打 | F9: =REPT("█",MIN(20,INT(D9/1000)))&REPT("░",20-MIN(20,INT(D9/1000))) -> ████████████████████ | H9: 仁雄店 | I9: 4 | J9: =SUMIF($H36:$H40,$H9,$K36:$K40) -> 89 | K9: =SUMIF($H$42:$H$46,$H9,$K$42:$K$46) -> 818.3 | L9: 78 | M9: =SUMIF(【你的全部獎金】!$A$7:$A$26,$H9,【你的全部獎金】!$Q$7:$Q$26) -> 90441.457 | N9: =IFERROR(M9/I9,0) -> 22610.364
A10: =ROW(A5) -> 5 | B10: =INDEX(【你的全部獎金】!$B$7:$B$26,MATCH($D10,【你的全部獎金】!$Q$7:$Q$26,0)) -> 邱雨蔚 | C10: =INDEX(【你的全部獎金】!$A$7:$A$26,MATCH($D10,【你的全部獎金】!$Q$7:$Q$26,0)) -> 陽明店 | D10: =LARGE(【你的全部獎金】!$Q$7:$Q$26,ROW(A5)) -> 36933.907 | E10: =IF(D10>=14000,"🏆全壘打",IF(D10>=10000,"⭐明星",IF(D10>=7000,"💪優秀",IF(D10>=4000,"✅合格","📈加油")))) -> 🏆全壘打 | F10: =REPT("█",MIN(20,INT(D10/1000)))&REPT("░",20-MIN(20,INT(D10/1000))) -> ████████████████████ | H10: 凱旋店 | I10: 4 | J10: =SUMIF($H37:$H41,$H10,$K37:$K41) -> 75 | K10: =SUMIF($H$42:$H$46,$H10,$K$42:$K$46) -> 672.4 | L10: 71 | M10: =SUMIF(【你的全部獎金】!$A$7:$A$26,$H10,【你的全部獎金】!$Q$7:$Q$26) -> 90937.111 | N10: =IFERROR(M10/I10,0) -> 22734.278
H11: 區督導 | I11: 黃庭鈞 | M11: =SUMIF(【你的全部獎金】!$A$7:$A$26,$H11,【你的全部獎金】!$Q$7:$Q$26) -> 45886.27
A13: 獎金等級分布 | H13: 📈 業績獎金 統計摘要
A14: 等級 | B14: 獎金範圍 | C14: 人數 | D14: 占比 | E14: 圖示 | H14: 總員工數 | I14: =SUM(I6:I10) -> 18 | J14: 人
A15: 🏆🏆 頂尖 | B15: $14,000以上 | C15: =COUNTIFS(【你的全部獎金】!$Q$7:$Q$26,">=14000") -> 13 | D15: =IFERROR(C15/19,0) -> 0.68421053 | E15: =REPT("●",C15) -> ●●●●●●●●●●●●● | H15: 總獎金 | I15: =SUM(M6:M11) -> 420328.59 | J15: 元
A16: 🏆明星 | B16: $10,000-$14000 | C16: =COUNTIFS(【你的全部獎金】!$Q$7:$Q$26,">=10000",【你的全部獎金】!$Q$7:$Q$26,"<14000") -> 2 | D16: =IFERROR(C16/19,0) -> 0.10526316 | E16: =REPT("●",C16) -> ●● | H16: 平均獎金 | I16: =I15/19 -> 22122.557 | J16: 元
A17: 💪 優秀 | B17: $7,000-$10000 | C17: =COUNTIFS(【你的全部獎金】!$Q$7:$Q$26,">=7000",【你的全部獎金】!$Q$7:$Q$26,"<10000") -> 2 | D17: =IFERROR(C17/19,0) -> 0.10526316 | E17: =REPT("●",C17) -> ●● | H17: 最高獎金 | I17: =MAX(【你的全部獎金】!Q7:Q26) -> 45886.27 | J17: 元
A18: ✅ 合格 | B18: $4,000-$7000 | C18: =COUNTIFS(【你的全部獎金】!$Q$7:$Q$26,">=4000",【你的全部獎金】!$Q$7:$Q$26,"<7000") -> 1 | D18: =IFERROR(C18/19,0) -> 0.052631579 | E18: =REPT("●",C18) -> ● | H18: 最低獎金 | I18: =MIN(【你的全部獎金】!Q7:Q26) -> 2850 | J18: 元
A19: 📈 加油 | B19: $4,000以下 | C19: =COUNTIFS(【你的全部獎金】!$Q$7:$Q$26,"<4000") -> 1 | D19: =IFERROR(C19/19,0) -> 0.052631579 | E19: =REPT("●",C19) -> ● | H19: 總AQ點數 | I19: =SUM(J6:J10) -> 368.5 | J19: 點
H21: 店毛利
I23: 店目標 | J23: 實際進度 | K23: 達成率 | L23: 獎金
B24: =100000/20 -> 5000 | H24: 鼎山店 | I24: =340000 -> 340000 | J24: 338442.49 | K24: =J24/I24 -> 0.99541909 | L24: =IF(J24<I24,"-8000","0") -> -8000
H25: 陽明店 | I25: =250000+(4762*6) -> 278572 | J25: 329851.2 | K25: =J25/I25 -> 1.1840788 | L25: =IF(J25<I25,"-8000","0") -> 0
H26: 後昌店 | I26: =240000+(4762*4) -> 259048 | J26: 325608.4 | K26: =J26/I26 -> 1.2569423 | L26: =IF(J26<I26,"-8000","0") -> 0
H27: 仁雄店 | I27: =340000 -> 340000 | J27: 420841.92 | K27: =J27/I27 -> 1.2377704 | L27: =IF(J27<I27,"-8000","0") -> 0
H28: 凱旋店 | I28: =320000+(4762*11) -> 372382 | J28: 427500.18 | K28: =J28/I28 -> 1.1480152 | L28: =IF(J28<I28,"-8000","0") -> 0
H30: AQ上線點數
I32: 台哥大目標 | J32: 0.7 | K32: 實際進度 | L32: 達成率 | M32: 獎金
H33: 鼎山店 | I33: 135 | J33: =I33*J32 -> 94.5 | K33: 98.5 | L33: =K33/J33 -> 1.042328 | M33: =IF(K33<J33,"-2500","0") -> 0
H34: 陽明店 | I34: 135 | J34: =I34*J32 -> 94.5 | K34: 65 | L34: =K34/J34 -> 0.68783069 | M34: =IF(K34<J34,"-2000","0") -> -2000
H35: 後昌店 | I35: 135 | J35: =I35*J32 -> 94.5 | K35: 41 | L35: =K35/J35 -> 0.43386243 | M35: =IF(K35<J35,"-2500","0") -> -2500
H36: 仁雄店 | I36: 135 | J36: =I36*J32 -> 94.5 | K36: 89 | L36: =K36/J36 -> 0.94179894 | M36: =IF(K36<J36,"-2500","0") -> -2500
H37: 凱旋店 | I37: 135 | J37: =I37*J32 -> 94.5 | K37: 75 | L37: =K37/J37 -> 0.79365079 | M37: =IF(K37<J37,"-2500","0") -> -2500
H39: RT上線點數
I41: 台哥大目標 | J41: 0.9 | K41: 實際進度 | L41: 達成率 | M41: 獎金
H42: 鼎山店 | I42: 1210 | J42: =I42*J41 -> 1089 | K42: 520.95 | L42: =K42/J42 -> 0.47837466 | M42: =IF(K42<J42,"-2500","0") -> -2500
H43: 陽明店 | I43: 921 | J43: =I43*J41 -> 828.9 | K43: 380.45 | L43: =K43/J43 -> 0.45898178 | M43: =IF(K43<J43,"-2000","0") -> -2000
H44: 後昌店 | I44: 921 | J44: =I44*J41 -> 828.9 | K44: 468.7 | L44: =K44/J44 -> 0.56544818 | M44: =IF(K44<J44,"-2500","0") -> -2500
H45: 仁雄店 | I45: 1210 | J45: =I45*J41 -> 1089 | K45: 818.3 | L45: =K45/J45 -> 0.75142332 | M45: =IF(K45<J45,"-2500","0") -> -2500
H46: 凱旋店 | I46: 1184 | J46: =I46*J41 -> 1065.6 | K46: 672.4 | L46: =K46/J46 -> 0.63100601 | M46: =IF(K46<J46,"-2500","0") -> -2500
H48: Netflix
I50: 台哥大目標 | J50: 0.5 | K50: 實際進度 | L50: 達成率 | M50: 獎金
...

Sheet 【你的全部獎金】
R2: 表現頂尖 | S2: =_xlfn.PERCENTILE.INC($R$7:$R$25,0.8) -> 4.7959
I3: 【你的全部獎金】 | N3: 總發出獎金 | Q3: =Q27 -> 420328.59 | R3: 在進度內 | S3: =_xlfn.PERCENTILE.INC($R$7:$R$25,0.4) -> 1.8892338
R4: 狀況不佳 | S4: =_xlfn.PERCENTILE.INC($R$7:$R$25,0.15) -> 0.76923077
B5: 員工資訊 | H5: 基礎獎金 | K5: 基礎獎金 | L5: 毛利分潤獎金 | M5: 🏆 追星獎 | O5: 全壘打獎金 | P5: KPI獎金 | Q5: 你的累計獎金 | R5: KPI分數 | S5: 總積分
A6: 店點 | B6: 姓名 | C6: 職級 | D6: AQ (100元/點) | E6: AQ999 (300元/件) | F6: RT升轉 (100元/件) | G6: RT1399 (100元/件) | H6: 特維 (100元/件) | I6: 寬頻 (500元/點) | J6: OP案(限5件) 每件500元 | K6: 累計獎金 | L6: 預估月底 | M6: 預估月底 | N6: 分數 | O6: 獎金 | P6: 淨獎金 | Q6: 獎金合計 | R6: 5大項目 | S6: 總積分/130000
A7: 仁雄店 | B7: 黃傑稜 | C7: 白金級 | D7: =SUMIF(■我的基礎獎金!$A$58:$A$77,$B7,■我的基礎獎金!$B$58:$B$77) -> 3550 | E7: =SUMIF(■我的基礎獎金!$A$58:$A$77,$B7,■我的基礎獎金!$C$58:$C$77) -> 900 | F7: =SUMIF(■我的基礎獎金!$A$58:$A$77,$B7,■我的基礎獎金!$D$58:$D$77) -> 2000 | G7: =SUMIF(■我的基礎獎金!$A$58:$A$77,$B7,■我的基礎獎金!$E$58:$E$77) -> 1400 | H7: =SUMIF(■我的基礎獎金!$A$58:$A$77,$B7,■我的基礎獎金!$F$58:$F$77) -> 800 | I7: =SUMIF(■我的基礎獎金!$A$58:$A$77,$B7,■我的基礎獎金!$G$58:$G$77) -> 625 | J7: =SUMIF(■我的基礎獎金!$A$58:$A$77,$B7,■我的基礎獎金!$H$58:$H$77) -> 0 | K7: =SUM(D7:J7) -> 9275 | L7: =SUMIF('2. 毛利分潤獎金'!$B$4:$B$32,$B7,'2. 毛利分潤獎金'!$H$4:$H$32) -> 23459.168 | M7: =SUMIF('🏆 追星獎'!$C$9:$C$27,$B7,'🏆 追星獎'!$G$9:$G$27) -> 8000 | N7: =SUMIF('3. 全壘打得分表'!$B$6:$B$25,$B7,'3. 全壘打得分表'!$AC$6:$AC$25) -> 12.264384 | O7: =SUMIF('3. 全壘打得分表'!$B$6:$B$25,$B7,'3. 全壘打得分表'!$E$6:$E$25) -> 5000 | P7: =SUMIF(■我的KPI獎金!$B:$B,$B7,■我的KPI獎金!$D:$D) -> -3500 | Q7: =SUM(K7,L7,M7,O7) -> 45734.168 | R7: =S7/130000+(SUMIF(數據!$A:$A,$B7,數據!$AI:$AI)) -> 5.3091028 | S7: =SUMIF('1. 基礎獎金 + 獎金排名'!$C:$C,$B7,'1. 基礎獎金 + 獎金排名'!$O:$O)+SUMIF('2. 毛利分潤獎金'!$B:$B,$B7,'2. 毛利分潤獎金'!$D:$D) -> 690183.36
A8: 陽明店 | B8: 邱雨蔚 | C8: 銀級 | D8: =SUMIF(■我的基礎獎金!$A$58:$A$77,$B8,■我的基礎獎金!$B$58:$B$77) -> 4700 | E8: =SUMIF(■我的基礎獎金!$A$58:$A$77,$B8,■我的基礎獎金!$C$58:$C$77) -> 1200 | F8: =SUMIF(■我的基礎獎金!$A$58:$A$77,$B8,■我的基礎獎金!$D$58:$D$77) -> 1300 | G8: =SUMIF(■我的基礎獎金!$A$58:$A$77,$B8,■我的基礎獎金!$E$58:$E$77) -> 800 | H8: =SUMIF(■我的基礎獎金!$A$58:$A$77,$B8,■我的基礎獎金!$F$58:$F$77) -> 500 | I8: =SUMIF(■我的基礎獎金!$A$58:$A$77,$B8,■我的基礎獎金!$G$58:$G$77) -> 500 | J8: =SUMIF(■我的基礎獎金!$A$58:$A$77,$B8,■我的基礎獎金!$H$58:$H$77) -> 0 | K8: =SUM(D8:J8) -> 9000 | L8: =SUMIF('2. 毛利分潤獎金'!$B$4:$B$32,$B8,'2. 毛利分潤獎金'!$H$4:$H$32) -> 20933.907 | M8: =SUMIF('🏆 追星獎'!$C$9:$C$27,$B8,'🏆 追星獎'!$G$9:$G$27) -> 3000 | N8: =SUMIF('3. 全壘打得分表'!$B$6:$B$25,$B8,'3. 全壘打得分表'!$AC$6:$AC$25) -> 11.364228 | O8: =SUMIF('3. 全壘打得分表'!$B$6:$B$25,$B8,'3. 全壘打得分表'!$E$6:$E$25) -> 4000 | P8: =SUMIF(■我的KPI獎金!$B:$B,$B8,■我的KPI獎金!$D:$D) -> -3500 | Q8: =SUM(K8,L8,M8,O8) -> 36933.907 | R8: =S8/130000+(SUMIF(數據!$A:$A,$B8,數據!$AI:$AI)) -> 4.7629087 | S8: =SUMIF('1. 基礎獎金 + 獎金排名'!$C:$C,$B8,'1. 基礎獎金 + 獎金排名'!$O:$O)+SUMIF('2. 毛利分潤獎金'!$B:$B,$B8,'2. 毛利分潤獎金'!$D:$D) -> 619178.13
A9: 區督導 | B9: 黃庭鈞 | C9: 黃金級 | D9: =SUMIF(■我的基礎獎金!$A$58:$A$77,$B9,■我的基礎獎金!$B$58:$B$77) -> 1650 | E9: =SUMIF(■我的基礎獎金!$A$58:$A$77,$B9,■我的基礎獎金!$C$58:$C$77) -> 300 | F9: =SUMIF(■我的基礎獎金!$A$58:$A$77,$B9,■我的基礎獎金!$D$58:$D$77) -> 1200 | G9: =SUMIF(■我的基礎獎金!$A$58:$A$77,$B9,■我的基礎獎金!$E$58:$E$77) -> 800 | H9: =SUMIF(■我的基礎獎金!$A$58:$A$77,$B9,■我的基礎獎金!$F$58:$F$77) -> 1400 | I9: =SUMIF(■我的基礎獎金!$A$58:$A$77,$B9,■我的基礎獎金!$G$58:$G$77) -> 2125 | J9: =SUMIF(■我的基礎獎金!$A$58:$A$77,$B9,■我的基礎獎金!$H$58:$H$77) -> 500 | K9: =SUM(D9:J9) -> 7975 | L9: =SUMIF('2. 毛利分潤獎金'!$B$4:$B$32,$B9,'2. 毛利分潤獎金'!$H$4:$H$32) -> 27911.27 | M9: =SUMIF('🏆 追星獎'!$C$9:$C$27,$B9,'🏆 追星獎'!$G$9:$G$27) -> 3000 | N9: =SUMIF('3. 全壘打得分表'!$B$6:$B$25,$B9,'3. 全壘打得分表'!$AC$6:$AC$25) -> 16.49649 | O9: =SUMIF('3. 全壘打得分表'!$B$6:$B$25,$B9,'3. 全壘打得分表'!$E$6:$E$25) -> 7000 | P9: =SUMIF(■我的KPI獎金!$B:$B,$B9,■我的KPI獎金!$D:$D) -> -2500 | Q9: =SUM(K9,L9,M9,O9) -> 45886.27 | R9: =S9/130000+(SUMIF(數據!$A:$A,$B9,數據!$AI:$AI)) -> 5.5978877 | S9: =SUMIF('1. 基礎獎金 + 獎金排名'!$C:$C,$B9,'1. 基礎獎金 + 獎金排名'!$O:$O)+SUMIF('2. 毛利分潤獎金'!$B:$B,$B9,'2. 毛利分潤獎金'!$D:$D) -> 727725.4
A10: 凱旋店 | B10: 陳宛姍 | C10: 白金級 | D10: =SUMIF(■我的基礎獎金!$A$58:$A$77,$B10,■我的基礎獎金!$B$58:$B$77) -> 2200 | E10: =SUMIF(■我的基礎獎金!$A$58:$A$77,$B10,■我的基礎獎金!$C$58:$C$77) -> 600 | F10: =SUMIF(■我的基礎獎金!$A$58:$A$77,$B10,■我的基礎獎金!$D$58:$D$77) -> 1700 | G10: =SUMIF(■我的基礎獎金!$A$58:$A$77,$B10,■我的基礎獎金!$E$58:$E$77) -> 800 | H10: =SUMIF(■我的基礎獎金!$A$58:$A$77,$B10,■我的基礎獎金!$F$58:$F$77) -> 1000 | I10: =SUMIF(■我的基礎獎金!$A$58:$A$77,$B10,■我的基礎獎金!$G$58:$G$77) -> 2750 | J10: =SUMIF(■我的基礎獎金!$A$58:$A$77,$B10,■我的基礎獎金!$H$58:$H$77) -> 0 | K10: =SUM(D10:J10) -> 9050 | L10: =SUMIF('2. 毛利分潤獎金'!$B$4:$B$32,$B10,'2. 毛利分潤獎金'!$H$4:$H$32) -> 28240.483 | M10: =SUMIF('🏆 追星獎'!$C$9:$C$27,$B10,'🏆 追星獎'!$G$9:$G$27) -> 3000 | N10: =SUMIF('3. 全壘打得分表'!$B$6:$B$25,$B10,'3. 全壘打得分表'!$AC$6:$AC$25) -> 12.239602 | O10: =SUMIF('3. 全壘打得分表'!$B$6:$B$25,$B10,'3. 全壘打得分表'!$E$6:$E$25) -> 5000 | P10: =SUMIF(■我的KPI獎金!$B:$B,$B10,■我的KPI獎金!$D:$D) -> -3500 | Q10: =SUM(K10,L10,M10,O10) -> 45290.483 | R10: =S10/130000+(SUMIF(數據!$A:$A,$B10,數據!$AI:$AI)) -> 5.7869973 | S10: =SUMIF('1. 基礎獎金 + 獎金排名'!$C:$C,$B10,'1. 基礎獎金 + 獎金排名'!$O:$O)+SUMIF('2. 毛利分潤獎金'!$B:$B,$B10,'2. 毛利分潤獎金'!$D:$D) -> 752309.65
A11: 後昌店 | B11: 黃閔聖 | C11: 銀級 | D11: =SUMIF(■我的基礎獎金!$A$58:$A$77,$B11,■我的基礎獎金!$B$58:$B$77) -> 1200 | E11: =SUMIF(■我的基礎獎金!$A$58:$A$77,$B11,■我的基礎獎金!$C$58:$C$77) -> 0 | F11: =SUMIF(■我的基礎獎金!$A$58:$A$77,$B11,■我的基礎獎金!$D$58:$D$77) -> 1000 | G11: =SUMIF(■我的基礎獎金!$A$58:$A$77,$B11,■我的基礎獎金!$E$58:$E$77) -> 600 | H11: =SUMIF(■我的基礎獎金!$A$58:$A$77,$B11,■我的基礎獎金!$F$58:$F$77) -> 1000 | I11: =SUMIF(■我的基礎獎金!$A$58:$A$77,$B11,■我的基礎獎金!$G$58:$G$77) -> 750 | J11: =SUMIF(■我的基礎獎金!$A$58:$A$77,$B11,■我的基礎獎金!$H$58:$H$77) -> 0 | K11: =SUM(D11:J11) -> 4550 | L11: =SUMIF('2. 毛利分潤獎金'!$B$4:$B$32,$B11,'2. 毛利分潤獎金'!$H$4:$H$32) -> 25720.014 | M11: =SUMIF('🏆 追星獎'!$C$9:$C$27,$B11,'🏆 追星獎'!$G$9:$G$27) -> 8000 | N11: =SUMIF('3. 全壘打得分表'!$B$6:$B$25,$B11,'3. 全壘打得分表'!$AC$6:$AC$25) -> 10.45549 | O11: =SUMIF('3. 全壘打得分表'!$B$6:$B$25,$B11,'3. 全壘打得分表'!$E$6:$E$25) -> 4000 | P11: =SUMIF(■我的KPI獎金!$B:$B,$B11,■我的KPI獎金!$D:$D) -> -2500 | Q11: =SUM(K11,L11,M11,O11) -> 42270.014 | R11: =S11/130000+(SUMIF(數據!$A:$A,$B11,數據!$AI:$AI)) -> 4.8453868 | S11: =SUMIF('1. 基礎獎金 + 獎金排名'!$C:$C,$B11,'1. 基礎獎金 + 獎金排名'!$O:$O)+SUMIF('2. 毛利分潤獎金'!$B:$B,$B11,'2. 毛利分潤獎金'!$D:$D) -> 629900.29
A12: 鼎山店 | B12: 陳亭安 | C12: 銀級 | D12: =SUMIF(■我的基礎獎金!$A$58:$A$77,$B12,■我的基礎獎金!$B$58:$B$77) -> 2350 | E12: =SUMIF(■我的基礎獎金!$A$58:$A$77,$B12,■我的基礎獎金!$C$58:$C$77) -> 600 | F12: =SUMIF(■我的基礎獎金!$A$58:$A$77,$B12,■我的基礎獎金!$D$58:$D$77) -> 1100 | G12: =SUMIF(■我的基礎獎金!$A$58:$A$77,$B12,■我的基礎獎金!$E$58:$E$77) -> 1100 | H12: =SUMIF(■我的基礎獎金!$A$58:$A$77,$B12,■我的基礎獎金!$F$58:$F$77) -> 700 | I12: =SUMIF(■我的基礎獎金!$A$58:$A$77,$B12,■我的基礎獎金!$G$58:$G$77) -> 0 | J12: =SUMIF(■我的基礎獎金!$A$58:$A$77,$B12,■我的基礎獎金!$H$58:$H$77) -> 0 | K12: =SUM(D12:J12) -> 5850 | L12: =SUMIF('2. 毛利分潤獎金'!$B$4:$B$32,$B12,'2. 毛利分潤獎金'!$H$4:$H$32) -> 10374.465 | M12: =SUMIF('🏆 追星獎'!$C$9:$C$27,$B12,'🏆 追星獎'!$G$9:$G$27) -> 0 | N12: =SUMIF('3. 全壘打得分表'!$B$6:$B$25,$B12,'3. 全壘打得分表'!$AC$6:$AC$25) -> 13.559183 | O12: =SUMIF('3. 全壘打得分表'!$B$6:$B$25,$B12,'3. 全壘打得分表'!$E$6:$E$25) -> 5000 | P12: =SUMIF(■我的KPI獎金!$B:$B,$B12,■我的KPI獎金!$D:$D) -> -2500 | Q12: =SUM(K12,L12,M12,O12) -> 21224.465 | R12: =S12/130000+(SUMIF(數據!$A:$A,$B12,數據!$AI:$AI)) -> 2.7172254 | S12: =SUMIF('1. 基礎獎金 + 獎金排名'!$C:$C,$B12,'1. 基礎獎金 + 獎金排名'!$O:$O)+SUMIF('2. 毛利分潤獎金'!$B:$B,$B12,'2. 毛利分潤獎金'!$D:$D) -> 353239.3
A13: 鼎山店 | B13: 劉家妘 | C13: 白金級 | D13: =SUMIF(■我的基礎獎金!$A$58:$A$77,$B13,■我的基礎獎金!$B$58:$B$77) -> 2550 | E13: =SUMIF(■我的基礎獎金!$A$58:$A$77,$B13,■我的基礎獎金!$C$58:$C$77) -> 900 | F13: =SUMIF(■我的基礎獎金!$A$58:$A$77,$B13,■我的基礎獎金!$D$58:$D$77) -> 500 | G13: =SUMIF(■我的基礎獎金!$A$58:$A$77,$B13,■我的基礎獎金!$E$58:$E$77) -> 700 | H13: =SUMIF(■我的基礎獎金!$A$58:$A$77,$B13,■我的基礎獎金!$F$58:$F$77) -> 1000 | I13: =SUMIF(■我的基礎獎金!$A$58:$A$77,$B13,■我的基礎獎金!$G$58:$G$77) -> 0 | J13: =SUMIF(■我的基礎獎金!$A$58:$A$77,$B13,■我的基礎獎金!$H$58:$H$77) -> 0 | K13: =SUM(D13:J13) -> 5650 | L13: =SUMIF('2. 毛利分潤獎金'!$B$4:$B$32,$B13,'2. 毛利分潤獎金'!$H$4:$H$32) -> 15501.341 | M13: =SUMIF('🏆 追星獎'!$C$9:$C$27,$B13,'🏆 追星獎'!$G$9:$G$27) -> 3000 | N13: =SUMIF('3. 全壘打得分表'!$B$6:$B$25,$B13,'3. 全壘打得分表'!$AC$6:$AC$25) -> 9.5491031 | O13: =SUMIF('3. 全壘打得分表'!$B$6:$B$25,$B13,'3. 全壘打得分表'!$E$6:$E$25) -> 3000 | P13: =SUMIF(■我的KPI獎金!$B:$B,$B13,■我的KPI獎金!$D:$D) -> -2500 | Q13: =SUM(K13,L13,M13,O13) -> 27151.341 | R13: =S13/130000+(SUMIF(數據!$A:$A,$B13,數據!$AI:$AI)) -> 3.3828986 | S13: =SUMIF('1. 基礎獎金 + 獎金排名'!$C:$C,$B13,'1. 基礎獎金 + 獎金排名'!$O:$O)+SUMIF('2. 毛利分潤獎金'!$B:$B,$B13,'2. 毛利分潤獎金'!$D:$D) -> 439776.81
A14: 凱旋店 | B14: 黃子珊 | C14: 銀級 | D14: =SUMIF(■我的基礎獎金!$A$58:$A$77,$B14,■我的基礎獎金!$B$58:$B$77) -> 2550 | E14: =SUMIF(■我的基礎獎金!$A$58:$A$77,$B14,■我的基礎獎金!$C$58:$C$77) -> 600 | F14: =SUMIF(■我的基礎獎金!$A$58:$A$77,$B14,■我的基礎獎金!$D$58:$D$77) -> 1100 | G14: =SUMIF(■我的基礎獎金!$A$58:$A$77,$B14,■我的基礎獎金!$E$58:$E$77) -> 700 | H14: =SUMIF(■我的基礎獎金!$A$58:$A$77,$B14,■我的基礎獎金!$F$58:$F$77) -> 900 | I14: =SUMIF(■我的基礎獎金!$A$58:$A$77,$B14,■我的基礎獎金!$G$58:$G$77) -> 1000 | J14: =SUMIF(■我的基礎獎金!$A$58:$A$77,$B14,■我的基礎獎金!$H$58:$H$77) -> 0 | K14: =SUM(D14:J14) -> 6850 | L14: =SUMIF('2. 毛利分潤獎金'!$B$4:$B$32,$B14,'2. 毛利分潤獎金'!$H$4:$H$32) -> 10024.66 | M14: =SUMIF('🏆 追星獎'!$C$9:$C$27,$B14,'🏆 追星獎'!$G$9:$G$27) -> 3000 | N14: =SUMIF('3. 全壘打得分表'!$B$6:$B$25,$B14,'3. 全壘打得分表'!$AC$6:$AC$25) -> 10.831384 | O14: =SUMIF('3. 全壘打得分表'!$B$6:$B$25,$B14,'3. 全壘打得分表'!$E$6:$E$25) -> 4000 | P14: =SUMIF(■我的KPI獎金!$B:$B,$B14,■我的KPI獎金!$D:$D) -> -4000 | Q14: =SUM(K14,L14,M14,O14) -> 23874.66 | R14: =S14/130000+(SUMIF(數據!$A:$A,$B14,數據!$AI:$AI)) -> 2.73264 | S14: =SUMIF('1. 基礎獎金 + 獎金排名'!$C:$C,$B14,'1. 基礎獎金 + 獎金排名'!$O:$O)+SUMIF('2. 毛利分潤獎金'!$B:$B,$B14,'2. 毛利分潤獎金'!$D:$D) -> 355243.2
A15: 後昌店 | B15: 郭家維 | C15: 銅級 | D15: =SUMIF(■我的基礎獎金!$A$58:$A$77,$B15,■我的基礎獎金!$B$58:$B$77) -> 1550 | E15: =SUMIF(■我的基礎獎金!$A$58:$A$77,$B15,■我的基礎獎金!$C$58:$C$77) -> 300 | F15: =SUMIF(■我的基礎獎金!$A$58:$A$77,$B15,■我的基礎獎金!$D$58:$D$77) -> 1300 | G15: =SUMIF(■我的基礎獎金!$A$58:$A$77,$B15,■我的基礎獎金!$E$58:$E$77) -> 800 | H15: =SUMIF(■我的基礎獎金!$A$58:$A$77,$B15,■我的基礎獎金!$F$58:$F$77) -> 1000 | I15: =SUMIF(■我的基礎獎金!$A$58:$A$77,$B15,■我的基礎獎金!$G$58:$G$77) -> 1375 | J15: =SUMIF(■我的基礎獎金!$A$58:$A$77,$B15,■我的基礎獎金!$H$58:$H$77) -> 0 | K15: =SUM(D15:J15) -> 6325 | L15: =SUMIF('2. 毛利分潤獎金'!$B$4:$B$32,$B15,'2. 毛利分潤獎金'!$H$4:$H$32) -> 8606.3806 | M15: =SUMIF('🏆 追星獎'!$C$9:$C$27,$B15,'🏆 追星獎'!$G$9:$G$27) -> 0 | N15: =SUMIF('3. 全壘打得分表'!$B$6:$B$25,$B15,'3. 全壘打得分表'!$AC$6:$AC$25) -> 13.148375 | O15: =SUMIF('3. 全壘打得分表'!$B$6:$B$25,$B15,'3. 全壘打得分表'!$E$6:$E$25) -> 5000 | P15: =SUMIF(■我的KPI獎金!$B:$B,$B15,■我的KPI獎金!$D:$D) -> -4000 | Q15: =SUM(K15,L15,M15,O15) -> 19931.381 | R15: =S15/130000+(SUMIF(數據!$A:$A,$B15,數據!$AI:$AI)) -> 2.4432893 | S15: =SUMIF('1. 基礎獎金 + 獎金排名'!$C:$C,$B15,'1. 基礎獎金 + 獎金排名'!$O:$O)+SUMIF('2. 毛利分潤獎金'!$B:$B,$B15,'2. 毛利分潤獎金'!$D:$D) -> 317627.61
A16: 仁雄店 | B16: 石佳穎 | C16: 銀級 | D16: =SUMIF(■我的基礎獎金!$A$58:$A$77,$B16,■我的基礎獎金!$B$58:$B$77) -> 1450 | E16: =SUMIF(■我的基礎獎金!$A$58:$A$77,$B16,■我的基礎獎金!$C$58:$C$77) -> 300 | F16: =SUMIF(■我的基礎獎金!$A$58:$A$77,$B16,■我的基礎獎金!$D$58:$D$77) -> 700 | G16: =SUMIF(■我的基礎獎金!$A$58:$A$77,$B16,■我的基礎獎金!$E$58:$E$77) -> 700 | H16: =SUMIF(■我的基礎獎金!$A$58:$A$77,$B16,■我的基礎獎金!$F$58:$F$77) -> 500 | I16: =SUMIF(■我的基礎獎金!$A$58:$A$77,$B16,■我的基礎獎金!$G$58:$G$77) -> 0 | J16: =SUMIF(■我的基礎獎金!$A$58:$A$77,$B16,■我的基礎獎金!$H$58:$H$77) -> 0 | K16: =SUM(D16:J16) -> 3650 | L16: =SUMIF('2. 毛利分潤獎金'!$B$4:$B$32,$B16,'2. 毛利分潤獎金'!$H$4:$H$32) -> 8287.5998 | M16: =SUMIF('🏆 追星獎'!$C$9:$C$27,$B16,'🏆 追星獎'!$G$9:$G$27) -> 0 | N16: =SUMIF('3. 全壘打得分表'!$B$6:$B$25,$B16,'3. 全壘打得分表'!$AC$6:$AC$25) -> 7.6515409 | O16: =SUMIF('3. 全壘打得分表'!$B$6:$B$25,$B16,'3. 全壘打得分表'!$E$6:$E$25) -> 0 | P16: =SUMIF(■我的KPI獎金!$B:$B,$B16,■我的KPI獎金!$D:$D) -> -4000 | Q16: =SUM(K16,L16,M16,O16) -> 11937.6 | R16: =S16/130000+(SUMIF(數據!$A:$A,$B16,數據!$AI:$AI)) -> 1.992323 | S16: =SUMIF('1. 基礎獎金 + 獎金排名'!$C:$C,$B16,'1. 基礎獎金 + 獎金排名'!$O:$O)+SUMIF('2. 毛利分潤獎金'!$B:$B,$B16,'2. 毛利分潤獎金'!$D:$D) -> 259002
A17: 鼎山店 | B17: 彥州 | C17: 石頭 | D17: =SUMIF(■我的基礎獎金!$A$58:$A$77,$B17,■我的基礎獎金!$B$58:$B$77) -> 3450 | E17: =SUMIF(■我的基礎獎金!$A$58:$A$77,$B17,■我的基礎獎金!$C$58:$C$77) -> 900 | F17: =SUMIF(■我的基礎獎金!$A$58:$A$77,$B17,■我的基礎獎金!$D$58:$D$77) -> 500 | G17: =SUMIF(■我的基礎獎金!$A$58:$A$77,$B17,■我的基礎獎金!$E$58:$E$77) -> 300 | H17: =SUMIF(■我的基礎獎金!$A$58:$A$77,$B17,■我的基礎獎金!$F$58:$F$77) -> 900 | I17: =SUMIF(■我的基礎獎金!$A$58:$A$77,$B17,■我的基礎獎金!$G$58:$G$77) -> 0 | J17: =SUMIF(■我的基礎獎金!$A$58:$A$77,$B17,■我的基礎獎金!$H$58:$H$77) -> 500 | K17: =SUM(D17:J17) -> 6550 | L17: =SUMIF('2. 毛利分潤獎金'!$B$4:$B$32,$B17,'2. 毛利分潤獎金'!$H$4:$H$32) -> 5000 | M17: =SUMIF('🏆 追星獎'!$C$9:$C$27,$B17,'🏆 追星獎'!$G$9:$G$27) -> 0 | N17: =SUMIF('3. 全壘打得分表'!$B$6:$B$25,$B17,'3. 全壘打得分表'!$AC$6:$AC$25) -> 9.3751481 | O17: =SUMIF('3. 全壘打得分表'!$B$6:$B$25,$B17,'3. 全壘打得分表'!$E$6:$E$25) -> 3000 | P17: =SUMIF(■我的KPI獎金!$B:$B,$B17,■我的KPI獎金!$D:$D) -> -3500 | Q17: =SUM(K17,L17,M17,O17) -> 14550 | R17: =S17/130000+(SUMIF(數據!$A:$A,$B17,數據!$AI:$AI)) -> 1.8634615 | S17: =SUMIF('1. 基礎獎金 + 獎金排名'!$C:$C,$B17,'1. 基礎獎金 + 獎金排名'!$O:$O)+SUMIF('2. 毛利分潤獎金'!$B:$B,$B17,'2. 毛利分潤獎金'!$D:$D) -> 242250
A18: 凱旋店 | B18: 林瑞獻 | C18: 石頭 | D18: =SUMIF(■我的基礎獎金!$A$58:$A$77,$B18,■我的基礎獎金!$B$58:$B$77) -> 1200 | E18: =SUMIF(■我的基礎獎金!$A$58:$A$77,$B18,■我的基礎獎金!$C$58:$C$77) -> 300 | F18: =SUMIF(■我的基礎獎金!$A$58:$A$77,$B18,■我的基礎獎金!$D$58:$D$77) -> 1000 | G18: =SUMIF(■我的基礎獎金!$A$58:$A$77,$B18,■我的基礎獎金!$E$58:$E$77) -> 200 | H18: =SUMIF(■我的基礎獎金!$A$58:$A$77,$B18,■我的基礎獎金!$F$58:$F$77) -> 500 | I18: =SUMIF(■我的基礎獎金!$A$58:$A$77,$B18,■我的基礎獎金!$G$58:$G$77) -> 1250 | J18: =SUMIF(■我的基礎獎金!$A$58:$A$77,$B18,■我的基礎獎金!$H$58:$H$77) -> 0 | K18: =SUM(D18:J18) -> 4450 | L18: =SUMIF('2. 毛利分潤獎金'!$B$4:$B$32,$B18,'2. 毛利分潤獎金'!$H$4:$H$32) -> 6621.9689 | M18: =SUMIF('🏆 追星獎'!$C$9:$C$27,$B18,'🏆 追星獎'!$G$9:$G$27) -> 0 | N18: =SUMIF('3. 全壘打得分表'!$B$6:$B$25,$B18,'3. 全壘打得分表'!$AC$6:$AC$25) -> 8.0263889 | O18: =SUMIF('3. 全壘打得分表'!$B$6:$B$25,$B18,'3. 全壘打得分表'!$E$6:$E$25) -> 3000 | P18: =SUMIF(■我的KPI獎金!$B:$B,$B18,■我的KPI獎金!$D:$D) -> -4000 | Q18: =SUM(K18,L18,M18,O18) -> 14071.969 | R18: =S18/130000+(SUMIF(數據!$A:$A,$B18,數據!$AI:$AI)) -> 1.7379952 | S18: =SUMIF('1. 基礎獎金 + 獎金排名'!$C:$C,$B18,'1. 基礎獎金 + 獎金排名'!$O:$O)+SUMIF('2. 毛利分潤獎金'!$B:$B,$B18,'2. 毛利分潤獎金'!$D:$D) -> 225939.38
... A25: 陽明店 | B25: 劉芳廷 | C25: 銀級 | D25: =SUMIF(■我的基礎獎金!$A$58:$A$77,$B25,■我的基礎獎金!$B$58:$B$77) -> 1350 | E25: =SUMIF(■我的基礎獎金!$A$58:$A$77,$B25,■我的基礎獎金!$C$58:$C$77) -> 300 | F25: =SUMIF(■我的基礎獎金!$A$58:$A$77,$B25,■我的基礎獎金!$D$58:$D$77) -> 400 | G25: =SUMIF(■我的基礎獎金!$A$58:$A$77,$B25,■我的基礎獎金!$E$58:$E$77) -> 600 | H25: =SUMIF(■我的基礎獎金!$A$58:$A$77,$B25,■我的基礎獎金!$F$58:$F$77) -> 200 | I25: =SUMIF(■我的基礎獎金!$A$58:$A$77,$B25,■我的基礎獎金!$G$58:$G$77) -> 0 | J25: =SUMIF(■我的基礎獎金!$A$58:$A$77,$B25,■我的基礎獎金!$H$58:$H$77) -> 0 | K25: =SUM(D25:J25) -> 2850 | L25: =SUMIF('2. 毛利分潤獎金'!$B$4:$B$32,$B25,'2. 毛利分潤獎金'!$H$4:$H$32) -> 0 | M25: =SUMIF('🏆 追星獎'!$C$9:$C$27,$B25,'🏆 追星獎'!$G$9:$G$27) -> 0 | N25: =SUMIF('3. 全壘打得分表'!$B$6:$B$25,$B25,'3. 全壘打得分表'!$AC$6:$AC$25) -> 5.7414557 | O25: =SUMIF('3. 全壘打得分表'!$B$6:$B$25,$B25,'3. 全壘打得分表'!$E$6:$E$25) -> 0 | P25: =SUMIF(■我的KPI獎金!$B:$B,$B25,■我的KPI獎金!$D:$D) -> -4500 | Q25: =SUM(K25,L25,M25,O25) -> 2850 | R25: =S25/130000+(SUMIF(數據!$A:$A,$B25,數據!$AI:$AI)) -> 0.53653846 | S25: =SUMIF('1. 基礎獎金 + 獎金排名'!$C:$C,$B25,'1. 基礎獎金 + 獎金排名'!$O:$O)+SUMIF('2. 毛利分潤獎金'!$B:$B,$B25,'2. 毛利分潤獎金'!$D:$D) -> 69750
A27: 總計 | D27: =SUM(D7:D26) -> 37100 | E27: =SUM(E7:E26) -> 9000 | F27: =SUM(F7:F26) -> 19200 | G27: =SUM(G7:G26) -> 12500 | H27: =SUM(H7:H26) -> 13900 | I27: =SUM(I7:I26) -> 13375 | J27: =SUM(J7:J26) -> 1000 | K27: =SUM(K7:K26) -> 106075 | ... Q27: =SUM(Q7:Q26) -> 420328.59
Q34: =Q27/21000000 -> 0.020015647

Sheet 1. 基礎獎金 + 獎金排名
A1: 🏆 基礎獎金工作表 VS 獎金排名
A2: 📊 KPI分數 = 全項總積分 ÷ 130,000 | 📊 積分倍數：AQ×25倍 RT×30倍 手機×15倍 | 排名高 = 貢獻度高！
A3: 📋 員工資訊 | E3: 🎯 AQ積分(×10) | H3: 📊 RT積分(×20) | L3: 💰 其他積分 | O3: 🏅 KPI排名結果
A4: 排名 | B4: 店點 | C4: 姓名 | D4: 職級 | E4: AQ獎金 | F4: AQ積分 (×25倍) | G4: AQ999+ | H4: RT升轉 (100元/件) | I4: RT1399 (100元/件) | J4: 特維 (100元/件) | K4: RT積分 (×30倍) | L4: 寬頻 (500元/點) | M4: OP案(限5件) 每件500元 | N4: 寬頻OP積分(×10倍) | O4: 你的總積分 | P4: KPI分數 | Q4: 基礎獎金 | R4: 達成狀態
A5: =RANK(P5,P$5:P$23,0) -> 10 | B5: =【你的全部獎金】!A23 -> 仁雄店 | C5: =【你的全部獎金】!B23 -> 郭紳鴻 | D5: =【你的全部獎金】!C23 -> 銅級 | E5: =SUMIF(【你的全部獎金】!$B$7:$B$26,$C5,【你的全部獎金】!$D$7:$D$26) -> 1150 | F5: =E5*25 -> 28750 | G5: =SUMIF(【你的全部獎金】!$B$7:$B$26,$C5,【你的全部獎金】!$E$7:$E$26) -> 300 | H5: =SUMIF(【你的全部獎金】!$B$7:$B$26,$C5,【你的全部獎金】!$F$7:$F$26) -> 1300 | I5: =SUMIF(【你的全部獎金】!$B$7:$B$26,$C5,【你的全部獎金】!$G$7:$G$26) -> 700 | J5: =SUMIF(【你的全部獎金】!$B$7:$B$26,$C5,【你的全部獎金】!$H$7:$H$26) -> 700 | K5: =SUM(H5,I5,J5)*30 -> 81000 | L5: =SUMIF(【你的全部獎金】!$B$7:$B$26,$C5,【你的全部獎金】!$I$7:$I$26) -> 1250 | M5: =SUMIF(【你的全部獎金】!$B$7:$B$26,$C5,【你的全部獎金】!$J$7:$J$26) -> 0 | N5: =SUM(L5,M5)*10 -> 12500 | O5: =SUM(F5,K5,N5) -> 122250 | P5: =O5/130000 -> 0.94038462 | Q5: =SUM(E5,G5,I5,J5,H5,L5) -> 5400 | R5: =REPT("█",MIN(20,INT(P5*2)))&REPT("░",20-MIN(20,INT(P5*2))) -> █░░░░░░░░░░░░░░░░░░░
A6: =RANK(P6,P$5:P$23,0) -> 6 | B6: =【你的全部獎金】!A12 -> 鼎山店 | C6: =【你的全部獎金】!B12 -> 陳亭安 | D6: =【你的全部獎金】!C12 -> 銀級 | E6: =SUMIF(【你的全部獎金】!$B$7:$B$26,$C6,【你的全部獎金】!$D$7:$D$26) -> 2350 | F6: =E6*25 -> 58750 | G6: =SUMIF(【你的全部獎金】!$B$7:$B$26,$C6,【你的全部獎金】!$E$7:$E$26) -> 600 | H6: =SUMIF(【你的全部獎金】!$B$7:$B$26,$C6,【你的全部獎金】!$F$7:$F$26) -> 1100 | I6: =SUMIF(【你的全部獎金】!$B$7:$B$26,$C6,【你的全部獎金】!$G$7:$G$26) -> 1100 | J6: =SUMIF(【你的全部獎金】!$B$7:$B$26,$C6,【你的全部獎金】!$H$7:$H$26) -> 700 | K6: =SUM(H6,I6,J6)*30 -> 87000 | L6: =SUMIF(【你的全部獎金】!$B$7:$B$26,$C6,【你的全部獎金】!$I$7:$I$26) -> 0 | M6: =SUMIF(【你的全部獎金】!$B$7:$B$26,$C6,【你的全部獎金】!$J$7:$J$26) -> 0 | N6: =SUM(L6,M6)*10 -> 0 | O6: =SUM(F6,K6,N6) -> 145750 | P6: =O6/130000 -> 1.1211538 | Q6: =SUM(E6,G6,I6,J6,H6,L6) -> 5850 | R6: =REPT("█",MIN(20,INT(P6*2)))&REPT("░",20-MIN(20,INT(P6*2))) -> ██░░░░░░░░░░░░░░░░░░
A7: =RANK(P7,P$5:P$23,0) -> 5 | B7: =【你的全部獎金】!A14 -> 凱旋店 | C7: =【你的全部獎金】!B14 -> 黃子珊 | D7: =【你的全部獎金】!C14 -> 銀級 | E7: =SUMIF(【你的全部獎金】!$B$7:$B$26,$C7,【你的全部獎金】!$D$7:$D$26) -> 2550 | F7: =E7*25 -> 63750 | G7: =SUMIF(【你的全部獎金】!$B$7:$B$26,$C7,【你的全部獎金】!$E$7:$E$26) -> 600 | H7: =SUMIF(【你的全部獎金】!$B$7:$B$26,$C7,【你的全部獎金】!$F$7:$F$26) -> 1100 | I7: =SUMIF(【你的全部獎金】!$B$7:$B$26,$C7,【你的全部獎金】!$G$7:$G$26) -> 700 | J7: =SUMIF(【你的全部獎金】!$B$7:$B$26,$C7,【你的全部獎金】!$H$7:$H$26) -> 900 | K7: =SUM(H7,I7,J7)*30 -> 81000 | L7: =SUMIF(【你的全部獎金】!$B$7:$B$26,$C7,【你的全部獎金】!$I$7:$I$26) -> 1000 | M7: =SUMIF(【你的全部獎金】!$B$7:$B$26,$C7,【你的全部獎金】!$J$7:$J$26) -> 0 | N7: =SUM(L7,M7)*10 -> 10000 | O7: =SUM(F7,K7,N7) -> 154750 | P7: =O7/130000 -> 1.1903846 | Q7: =SUM(E7,G7,I7,J7,H7,L7) -> 6850 | R7: =REPT("█",MIN(20,INT(P7*2)))&REPT("░",20-MIN(20,INT(P7*2))) -> ██░░░░░░░░░░░░░░░░░░
A8: =RANK(P8,P$5:P$23,0) -> 14 | B8: =【你的全部獎金】!A18 -> 凱旋店 | C8: =【你的全部獎金】!B18 -> 林瑞獻 | D8: =【你的全部獎金】!C18 -> 石頭 | E8: =SUMIF(【你的全部獎金】!$B$7:$B$26,$C8,【你的全部獎金】!$D$7:$D$26) -> 1200 | F8: =E8*25 -> 30000 | G8: =SUMIF(【你的全部獎金】!$B$7:$B$26,$C8,【你的全部獎金】!$E$7:$E$26) -> 300 | H8: =SUMIF(【你的全部獎金】!$B$7:$B$26,$C8,【你的全部獎金】!$F$7:$F$26) -> 1000 | I8: =SUMIF(【你的全部獎金】!$B$7:$B$26,$C8,【你的全部獎金】!$G$7:$G$26) -> 200 | J8: =SUMIF(【你的全部獎金】!$B$7:$B$26,$C8,【你的全部獎金】!$H$7:$H$26) -> 500 | K8: =SUM(H8,I8,J8)*30 -> 51000 | L8: =SUMIF(【你的全部獎金】!$B$7:$B$26,$C8,【你的全部獎金】!$I$7:$I$26) -> 1250 | M8: =SUMIF(【你的全部獎金】!$B$7:$B$26,$C8,【你的全部獎金】!$J$7:$J$26) -> 0 | N8: =SUM(L8,M8)*10 -> 12500 | O8: =SUM(F8,K8,N8) -> 93500 | P8: =O8/130000 -> 0.71923077 | Q8: =SUM(E8,G8,I8,J8,H8,L8) -> 4450 | R8: =REPT("█",MIN(20,INT(P8*2)))&REPT("░",20-MIN(20,INT(P8*2))) -> █░░░░░░░░░░░░░░░░░░░
A9: =RANK(P9,P$5:P$23,0) -> 18 | B9: =【你的全部獎金】!A21 -> 凱旋店 | C9: =【你的全部獎金】!B21 -> 劉宗翰 | D9: =【你的全部獎金】!C21 -> 小石頭 | E9: =SUMIF(【你的全部獎金】!$B$7:$B$26,$C9,【你的全部獎金】!$D$7:$D$26) -> 800 | F9: =E9*25 -> 20000 | G9: =SUMIF(【你的全部獎金】!$B$7:$B$26,$C9,【你的全部獎金】!$E$7:$E$26) -> 0 | H9: =SUMIF(【你的全部獎金】!$B$7:$B$26,$C9,【你的全部獎金】!$F$7:$F$26) -> 1100 | I9: =SUMIF(【你的全部獎金】!$B$7:$B$26,$C9,【你的全部獎金】!$G$7:$G$26) -> 500 | J9: =SUMIF(【你的全部獎金】!$B$7:$B$26,$C9,【你的全部獎金】!$H$7:$H$26) -> 300 | K9: =SUM(H9,I9,J9)*30 -> 57000 | L9: =SUMIF(【你的全部獎金】!$B$7:$B$26,$C9,【你的全部獎金】!$I$7:$I$26) -> 0 | M9: =SUMIF(【你的全部獎金】!$B$7:$B$26,$C9,【你的全部獎金】!$J$7:$J$26) -> 0 | N9: =SUM(L9,M9)*10 -> 0 | O9: =SUM(F9,K9,N9) -> 77000 | P9: =O9/130000 -> 0.59230769 | Q9: =SUM(E9,G9,I9,J9,H9,L9) -> 2700 | R9: =REPT("█",MIN(20,INT(P9*2)))&REPT("░",20-MIN(20,INT(P9*2))) -> █░░░░░░░░░░░░░░░░░░░
A10: =RANK(P10,P$5:P$23,0) -> 19 | B10: =【你的全部獎金】!A25 -> 陽明店 | C10: =【你的全部獎金】!B25 -> 劉芳廷 | D10: =【你的全部獎金】!C25 -> 銀級 | E10: =SUMIF(【你的全部獎金】!$B$7:$B$26,$C10,【你的全部獎金】!$D$7:$D$26) -> 1350 | F10: =E10*25 -> 33750 | G10: =SUMIF(【你的全部獎金】!$B$7:$B$26,$C10,【你的全部獎金】!$E$7:$E$26) -> 300 | H10: =SUMIF(【你的全部獎金】!$B$7:$B$26,$C10,【你的全部獎金】!$F$7:$F$26) -> 400 | I10: =SUMIF(【你的全部獎金】!$B$7:$B$26,$C10,【你的全部獎金】!$G$7:$G$26) -> 600 | J10: =SUMIF(【你的全部獎金】!$B$7:$B$26,$C10,【你的全部獎金】!$H$7:$H$26) -> 200 | K10: =SUM(H10,I10,J10)*30 -> 36000 | L10: =SUMIF(【你的全部獎金】!$B$7:$B$26,$C10,【你的全部獎金】!$I$7:$I$26) -> 0 | M10: =SUMIF(【你的全部獎金】!$B$7:$B$26,$C10,【你的全部獎金】!$J$7:$J$26) -> 0 | N10: =SUM(L10,M10)*10 -> 0 | O10: =SUM(F10,K10,N10) -> 69750 | P10: =O10/130000 -> 0.53653846 | Q10: =SUM(E10,G10,I10,J10,H10,L10) -> 2850 | R10: =REPT("█",MIN(20,INT(P10*2)))&REPT("░",20-MIN(20,INT(P10*2))) -> █░░░░░░░░░░░░░░░░░░░
A11: =RANK(P11,P$5:$P$23,0) -> 3 | B11: =【你的全部獎金】!A10 -> 凱旋店 | C11: =【你的全部獎金】!B10 -> 陳宛姍 | D11: =【你的全部獎金】!C10 -> 白金級 | E11: =SUMIF(【你的全部獎金】!$B$7:$B$26,$C11,【你的全部獎金】!$D$7:$D$26) -> 2200 | F11: =E11*25 -> 55000 | G11: =SUMIF(【你的全部獎金】!$B$7:$B$26,$C11,【你的全部獎金】!$E$7:$E$26) -> 600 | H11: =SUMIF(【你的全部獎金】!$B$7:$B$26,$C11,【你的全部獎金】!$F$7:$F$26) -> 1700 | I11: =SUMIF(【你的全部獎金】!$B$7:$B$26,$C11,【你的全部獎金】!$G$7:$G$26) -> 800 | J11: =SUMIF(【你的全部獎金】!$B$7:$B$26,$C11,【你的全部獎金】!$H$7:$H$26) -> 1000 | K11: =SUM(H11,I11,J11)*30 -> 105000 | L11: =SUMIF(【你的全部獎金】!$B$7:$B$26,$C11,【你的全部獎金】!$I$7:$I$26) -> 2750 | M11: =SUMIF(【你的全部獎金】!$B$7:$B$26,$C11,【你的全部獎金】!$J$7:$J$26) -> 0 | N11: =SUM(L11,M11)*10 -> 27500 | O11: =SUM(F11,K11,N11) -> 187500 | P11: =O11/130000 -> 1.4423077 | Q11: =SUM(E11,G11,I11,J11,H11,L11) -> 9050
A12: =RANK(P12,P$5:P$23,0) -> 9 | B12: =【你的全部獎金】!A13 -> 鼎山店 | C12: =【你的全部獎金】!B13 -> 劉家妘 | D12: =【你的全部獎金】!C13 -> 白金級 | E12: =SUMIF(【你的全部獎金】!$B$7:$B$26,$C12,【你的全部獎金】!$D$7:$D$26) -> 2550 | F12: =E12*25 -> 63750 | G12: =SUMIF(【你的全部獎金】!$B$7:$B$26,$C12,【你的全部獎金】!$E$7:$E$26) -> 900 | H12: =SUMIF(【你的全部獎金】!$B$7:$B$26,$C12,【你的全部獎金】!$F$7:$F$26) -> 500 | I12: =SUMIF(【你的全部獎金】!$B$7:$B$26,$C12,【你的全部獎金】!$G$7:$G$26) -> 700 | J12: =SUMIF(【你的全部獎金】!$B$7:$B$26,$C12,【你的全部獎金】!$H$7:$H$26) -> 1000 | K12: =SUM(H12,I12,J12)*30 -> 66000 | L12: =SUMIF(【你的全部獎金】!$B$7:$B$26,$C12,【你的全部獎金】!$I$7:$I$26) -> 0 | M12: =SUMIF(【你的全部獎金】!$B$7:$B$26,$C12,【你的全部獎金】!$J$7:$J$26) -> 0 | N12: =SUM(L12,M12)*10 -> 0 | O12: =SUM(F12,K12,N12) -> 129750 | P12: =O12/130000 -> 0.99807692 | Q12: =SUM(E12,G12,I12,J12,H12,L12) -> 5650 | R12: =REPT("█",MIN(20,INT(P12*2)))&REPT("░",20-MIN(20,INT(P12*2))) -> █░░░░░░░░░░░░░░░░░░░
A13: =RANK(P13,P$5:P$23,0) -> 12 | B13: =【你的全部獎金】!A22 -> 鼎山店 | C13: =【你的全部獎金】!B22 -> 高琦茗 | D13: =【你的全部獎金】!C22 -> 銅級 | E13: =SUMIF(【你的全部獎金】!$B$7:$B$26,$C13,【你的全部獎金】!$D$7:$D$26) -> 1500 | F13: =E13*25 -> 37500 | G13: =SUMIF(【你的全部獎金】!$B$7:$B$26,$C13,【你的全部獎金】!$E$7:$E$26) -> 600 | H13: =SUMIF(【你的全部獎金】!$B$7:$B$26,$C13,【你的全部獎金】!$F$7:$F$26) -> 900 | I13: =SUMIF(【你的全部獎金】!$B$7:$B$26,$C13,【你的全部獎金】!$G$7:$G$26) -> 400 | J13: =SUMIF(【你的全部獎金】!$B$7:$B$26,$C13,【你的全部獎金】!$H$7:$H$26) -> 700 | K13: =SUM(H13,I13,J13)*30 -> 60000 | L13: =SUMIF(【你的全部獎金】!$B$7:$B$26,$C13,【你的全部獎金】!$I$7:$I$26) -> 1000 | M13: =SUMIF(【你的全部獎金】!$B$7:$B$26,$C13,【你的全部獎金】!$J$7:$J$26) -> 0 | N13: =SUM(L13,M13)*10 -> 10000 | O13: =SUM(F13,K13,N13) -> 107500 | P13: =O13/130000 -> 0.82692308 | Q13: =SUM(E13,G13,I13,J13,H13,L13) -> 5100 | R13: =REPT("█",MIN(20,INT(P13*2)))&REPT("░",20-MIN(20,INT(P13*2))) -> █░░░░░░░░░░░░░░░░░░░
A14: =RANK(P14,P$5:P$23,0) -> 2 | B14: =【你的全部獎金】!A8 -> 陽明店 | C14: =【你的全部獎金】!B8 -> 邱雨蔚 | D14: =【你的全部獎金】!C8 -> 銀級 | E14: =SUMIF(【你的全部獎金】!$B$7:$B$26,$C14,【你的全部獎金】!$D$7:$D$26) -> 4700 | F14: =E14*25 -> 117500 | G14: =SUMIF(【你的全部獎金】!$B$7:$B$26,$C14,【你的全部獎金】!$E$7:$E$26) -> 1200 | H14: =SUMIF(【你的全部獎金】!$B$7:$B$26,$C14,【你的全部獎金】!$F$7:$F$26) -> 1300 | I14: =SUMIF(【你的全部獎金】!$B$7:$B$26,$C14,【你的全部獎金】!$G$7:$G$26) -> 800 | J14: =SUMIF(【你的全部獎金】!$B$7:$B$26,$C14,【你的全部獎金】!$H$7:$H$26) -> 500 | K14: =SUM(H14,I14,J14)*30 -> 78000 | L14: =SUMIF(【你的全部獎金】!$B$7:$B$26,$C14,【你的全部獎金】!$I$7:$I$26) -> 500 | M14: =SUMIF(【你的全部獎金】!$B$7:$B$26,$C14,【你的全部獎金】!$J$7:$J$26) -> 0 | N14: =SUM(L14,M14)*10 -> 5000 | O14: =SUM(F14,K14,N14) -> 200500 | P14: =O14/130000 -> 1.5423077 | Q14: =SUM(E14,G14,I14,J14,H14,L14) -> 9000 | R14: =REPT("█",MIN(20,INT(P14*2)))&REPT("░",20-MIN(20,INT(P14*2))) -> ███░░░░░░░░░░░░░░░░░
A15: =RANK(P15,P$5:P$23,0) -> 13 | B15: =【你的全部獎金】!A19 -> 仁雄店 | C15: =【你的全部獎金】!B19 -> 蔡冠廷 | D15: =【你的全部獎金】!C19 -> 石頭 | E15: =SUMIF(【你的全部獎金】!$B$7:$B$26,$C15,【你的全部獎金】!$D$7:$D$26) -> 1200 | F15: =E15*25 -> 30000 | G15: =SUMIF(【你的全部獎金】!$B$7:$B$26,$C15,【你的全部獎金】!$E$7:$E$26) -> 300 | H15: =SUMIF(【你的全部獎金】!$B$7:$B$26,$C15,【你的全部獎金】!$F$7:$F$26) -> 800 | I15: =SUMIF(【你的全部獎金】!$B$7:$B$26,$C15,【你的全部獎金】!$G$7:$G$26) -> 700 | J15: =SUMIF(【你的全部獎金】!$B$7:$B$26,$C15,【你的全部獎金】!$H$7:$H$26) -> 700 | K15: =SUM(H15,I15,J15)*30 -> 66000 | L15: =SUMIF(【你的全部獎金】!$B$7:$B$26,$C15,【你的全部獎金】!$I$7:$I$26) -> 0 | M15: =SUMIF(【你的全部獎金】!$B$7:$B$26,$C15,【你的全部獎金】!$J$7:$J$26) -> 0 | N15: =SUM(L15,M15)*10 -> 0 | O15: =SUM(F15,K15,N15) -> 96000 | P15: =O15/130000 -> 0.73846154 | Q15: =SUM(E15,G15,I15,J15,H15,L15) -> 3700 | R15: =REPT("█",MIN(20,INT(P15*2)))&REPT("░",20-MIN(20,INT(P15*2))) -> █░░░░░░░░░░░░░░░░░░░
A16: =RANK(P16,P$5:P$23,0) -> 4 | B16: =【你的全部獎金】!A9 -> 區督導 | C16: =【你的全部獎金】!B9 -> 黃庭鈞 | D16: =【你的全部獎金】!C9 -> 黃金級 | E16: =SUMIF(【你的全部獎金】!$B$7:$B$26,$C16,【你的全部獎金】!$D$7:$D$26) -> 1650 | F16: =E16*25 -> 41250 | G16: =SUMIF(【你的全部獎金】!$B$7:$B$26,$C16,【你的全部獎金】!$E$7:$E$26) -> 300 | H16: =SUMIF(【你的全部獎金】!$B$7:$B$26,$C16,【你的全部獎金】!$F$7:$F$26) -> 1200 | I16: =SUMIF(【你的全部獎金】!$B$7:$B$26,$C16,【你的全部獎金】!$G$7:$G$26) -> 800 | J16: =SUMIF(【你的全部獎金】!$B$7:$B$26,$C16,【你的全部獎金】!$H$7:$H$26) -> 1400 | K16: =SUM(H16,I16,J16)*30 -> 102000 | L16: =SUMIF(【你的全部獎金】!$B$7:$B$26,$C16,【你的全部獎金】!$I$7:$I$26) -> 2125 | M16: =SUMIF(【你的全部獎金】!$B$7:$B$26,$C16,【你的全部獎金】!$J$7:$J$26) -> 500 | N16: =SUM(L16,M16)*10 -> 26250 | O16: =SUM(F16,K16,N16) -> 169500 | P16: =O16/130000 -> 1.3038462 | Q16: =SUM(E16,G16,I16,J16,H16,L16) -> 7475 | R16: =REPT("█",MIN(20,INT(P16*2)))&REPT("░",20-MIN(20,INT(P16*2))) -> ██░░░░░░░░░░░░░░░░░░
A17: =RANK(P17,P$5:P$23,0) -> 7 | B17: =【你的全部獎金】!A15 -> 後昌店 | C17: =【你的全部獎金】!B15 -> 郭家維 | D17: =【你的全部獎金】!C15 -> 銅級 | E17: =SUMIF(【你的全部獎金】!$B$7:$B$26,$C17,【你的全部獎金】!$D$7:$D$26) -> 1550 | F17: =E17*25 -> 38750 | G17: =SUMIF(【你的全部獎金】!$B$7:$B$26,$C17,【你的全部獎金】!$E$7:$E$26) -> 300 | H17: =SUMIF(【你的全部獎金】!$B$7:$B$26,$C17,【你的全部獎金】!$F$7:$F$26) -> 1300 | I17: =SUMIF(【你的全部獎金】!$B$7:$B$26,$C17,【你的全部獎金】!$G$7:$G$26) -> 800 | J17: =SUMIF(【你的全部獎金】!$B$7:$B$26,$C17,【你的全部獎金】!$H$7:$H$26) -> 1000 | K17: =SUM(H17,I17,J17)*30 -> 93000 | L17: =SUMIF(【你的全部獎金】!$B$7:$B$26,$C17,【你的全部獎金】!$I$7:$I$26) -> 1375 | M17: =SUMIF(【你的全部獎金】!$B$7:$B$26,$C17,【你的全部獎金】!$J$7:$J$26) -> 0 | N17: =SUM(L17,M17)*10 -> 13750 | O17: =SUM(F17,K17,N17) -> 145500 | P17: =O17/130000 -> 1.1192308 | Q17: =SUM(E17,G17,I17,J17,H17,L17) -> 6325 | R17: =REPT("█",MIN(20,INT(P17*2)))&REPT("░",20-MIN(20,INT(P17*2))) -> ██░░░░░░░░░░░░░░░░░░
A18: =RANK(P18,P$5:P$23,0) -> 11 | B18: =【你的全部獎金】!A11 -> 後昌店 | C18: =【你的全部獎金】!B11 -> 黃閔聖 | D18: =【你的全部獎金】!C11 -> 銀級 | E18: =SUMIF(【你的全部獎金】!$B$7:$B$26,$C18,【你的全部獎金】!$D$7:$D$26) -> 1200 | F18: =E18*25 -> 30000 | G18: =SUMIF(【你的全部獎金】!$B$7:$B$26,$C18,【你的全部獎金】!$E$7:$E$26) -> 0 | H18: =SUMIF(【你的全部獎金】!$B$7:$B$26,$C18,【你的全部獎金】!$F$7:$F$26) -> 1000 | I18: =SUMIF(【你的全部獎金】!$B$7:$B$26,$C18,【你的全部獎金】!$G$7:$G$26) -> 600 | J18: =SUMIF(【你的全部獎金】!$B$7:$B$26,$C18,【你的全部獎金】!$H$7:$H$26) -> 1000 | K18: =SUM(H18,I18,J18)*30 -> 78000 | L18: =SUMIF(【你的全部獎金】!$B$7:$B$26,$C18,【你的全部獎金】!$I$7:$I$26) -> 750 | M18: =SUMIF(【你的全部獎金】!$B$7:$B$26,$C18,【你的全部獎金】!$J$7:$J$26) -> 0 | N18: =SUM(L18,M18)*10 -> 7500 | O18: =SUM(F18,K18,N18) -> 115500 | P18: =O18/130000 -> 0.88846154 | Q18: =SUM(E18,G18,I18,J18,H18,L18) -> 4550 | R18: =REPT("█",MIN(20,INT(P18*2)))&REPT("░",20-MIN(20,INT(P18*2))) -> █░░░░░░░░░░░░░░░░░░░
A19: =RANK(P19,P$5:P$23,0) -> 17 | B19: =【你的全部獎金】!A24 -> 後昌店 | C19: =【你的全部獎金】!B24 -> 秦曼芯 | D19: =【你的全部獎金】!C24 -> 石頭 | E19: =SUMIF(【你的全部獎金】!$B$7:$B$26,$C19,【你的全部獎金】!$D$7:$D$26) -> 1500 | F19: =E19*25 -> 37500 | G19: =SUMIF(【你的全部獎金】!$B$7:$B$26,$C19,【你的全部獎金】!$E$7:$E$26) -> 300 | H19: =SUMIF(【你的全部獎金】!$B$7:$B$26,$C19,【你的全部獎金】!$F$7:$F$26) -> 500 | I19: =SUMIF(【你的全部獎金】!$B$7:$B$26,$C19,【你的全部獎金】!$G$7:$G$26) -> 400 | J19: =SUMIF(【你的全部獎金】!$B$7:$B$26,$C19,【你的全部獎金】!$H$7:$H$26) -> 600 | K19: =SUM(H19,I19,J19)*30 -> 45000 | L19: =SUMIF(【你的全部獎金】!$B$7:$B$26,$C19,【你的全部獎金】!$I$7:$I$26) -> 0 | M19: =SUMIF(【你的全部獎金】!$B$7:$B$26,$C19,【你的全部獎金】!$J$7:$J$26) -> 0 | N19: =SUM(L19,M19)*10 -> 0 | O19: =SUM(F19,K19,N19) -> 82500 | P19: =O19/130000 -> 0.63461538 | Q19: =SUM(E19,G19,I19,J19,H19,L19) -> 3300 | R19: =REPT("█",MIN(20,INT(P19*2)))&REPT("░",20-MIN(20,INT(P19*2))) -> █░░░░░░░░░░░░░░░░░░░
A20: =RANK(P20,P$5:P$23,0) -> 8 | B20: =【你的全部獎金】!A17 -> 鼎山店 | C20: =【你的全部獎金】!B17 -> 彥州 | D20: =【你的全部獎金】!C17 -> 石頭 | E20: =SUMIF(【你的全部獎金】!$B$7:$B$26,$C20,【你的全部獎金】!$D$7:$D$26) -> 3450 | F20: =E20*25 -> 86250 | G20: =SUMIF(【你的全部獎金】!$B$7:$B$26,$C20,【你的全部獎金】!$E$7:$E$26) -> 900 | H20: =SUMIF(【你的全部獎金】!$B$7:$B$26,$C20,【你的全部獎金】!$F$7:$F$26) -> 500 | I20: =SUMIF(【你的全部獎金】!$B$7:$B$26,$C20,【你的全部獎金】!$G$7:$G$26) -> 300 | J20: =SUMIF(【你的全部獎金】!$B$7:$B$26,$C20,【你的全部獎金】!$H$7:$H$26) -> 900 | K20: =SUM(H20,I20,J20)*30 -> 51000 | L20: =SUMIF(【你的全部獎金】!$B$7:$B$26,$C20,【你的全部獎金】!$I$7:$I$26) -> 0 | M20: =SUMIF(【你的全部獎金】!$B$7:$B$26,$C20,【你的全部獎金】!$J$7:$J$26) -> 500 | N20: =SUM(L20,M20)*10 -> 5000 | O20: =SUM(F20,K20,N20) -> 142250 | P20: =O20/130000 -> 1.0942308 | Q20: =SUM(E20,G20,I20,J20,H20,L20) -> 6050 | R20: =REPT("█",MIN(20,INT(P20*2)))&REPT("░",20-MIN(20,INT(P20*2))) -> ██░░░░░░░░░░░░░░░░░░
A21: =RANK(P21,P$5:P$23,0) -> 16 | B21: =【你的全部獎金】!A20 -> 陽明店 | C21: =【你的全部獎金】!B20 -> 林庭逸 | D21: =【你的全部獎金】!C20 -> 石頭 | E21: =SUMIF(【你的全部獎金】!$B$7:$B$26,$C21,【你的全部獎金】!$D$7:$D$26) -> 1200 | F21: =E21*25 -> 30000 | G21: =SUMIF(【你的全部獎金】!$B$7:$B$26,$C21,【你的全部獎金】!$E$7:$E$26) -> 300 | H21: =SUMIF(【你的全部獎金】!$B$7:$B$26,$C21,【你的全部獎金】!$F$7:$F$26) -> 800 | I21: =SUMIF(【你的全部獎金】!$B$7:$B$26,$C21,【你的全部獎金】!$G$7:$G$26) -> 300 | J21: =SUMIF(【你的全部獎金】!$B$7:$B$26,$C21,【你的全部獎金】!$H$7:$H$26) -> 500 | K21: =SUM(H21,I21,J21)*30 -> 48000 | L21: =SUMIF(【你的全部獎金】!$B$7:$B$26,$C21,【你的全部獎金】!$I$7:$I$26) -> 750 | M21: =SUMIF(【你的全部獎金】!$B$7:$B$26,$C21,【你的全部獎金】!$J$7:$J$26) -> 0 | N21: =SUM(L21,M21)*10 -> 7500 | O21: =SUM(F21,K21,N21) -> 85500 | P21: =O21/130000 -> 0.65769231 | Q21: =SUM(E21,G21,I21,J21,H21,L21) -> 3850 | R21: =REPT("█",MIN(20,INT(P21*2)))&REPT("░",20-MIN(20,INT(P21*2))) -> █░░░░░░░░░░░░░░░░░░░
A22: =RANK(P22,P$5:P$23,0) -> 1 | B22: =【你的全部獎金】!A7 -> 仁雄店 | C22: =【你的全部獎金】!B7 -> 黃傑稜 | D22: =【你的全部獎金】!C7 -> 白金級 | E22: =SUMIF(【你的全部獎金】!$B$7:$B$26,$C22,【你的全部獎金】!$D$7:$D$26) -> 3550 | F22: =E22*25 -> 88750 | G22: =SUMIF(【你的全部獎金】!$B$7:$B$26,$C22,【你的全部獎金】!$E$7:$E$26) -> 900 | H22: =SUMIF(【你的全部獎金】!$B$7:$B$26,$C22,【你的全部獎金】!$F$7:$F$26) -> 2000 | I22: =SUMIF(【你的全部獎金】!$B$7:$B$26,$C22,【你的全部獎金】!$G$7:$G$26) -> 1400 | J22: =SUMIF(【你的全部獎金】!$B$7:$B$26,$C22,【你的全部獎金】!$H$7:$H$26) -> 800 | K22: =SUM(H22,I22,J22)*30 -> 126000 | L22: =SUMIF(【你的全部獎金】!$B$7:$B$26,$C22,【你的全部獎金】!$I$7:$I$26) -> 625 | M22: =SUMIF(【你的全部獎金】!$B$7:$B$26,$C22,【你的全部獎金】!$J$7:$J$26) -> 0 | N22: =SUM(L22,M22)*10 -> 6250 | O22: =SUM(F22,K22,N22) -> 221000 | P22: =O22/130000 -> 1.7 | Q22: =SUM(E22,G22,I22,J22,H22,L22) -> 9275 | R22: =REPT("█",MIN(20,INT(P22*2)))&REPT("░",20-MIN(20,INT(P22*2))) -> ███░░░░░░░░░░░░░░░░░
A23: =RANK(P23,P$5:P$23,0) -> 15 | B23: =【你的全部獎金】!A16 -> 仁雄店 | C23: =【你的全部獎金】!B16 -> 石佳穎 | D23: =【你的全部獎金】!C16 -> 銀級 | E23: =SUMIF(【你的全部獎金】!$B$7:$B$26,$C23,【你的全部獎金】!$D$7:$D$26) -> 1450 | F23: =E23*25 -> 36250 | G23: =SUMIF(【你的全部獎金】!$B$7:$B$26,$C23,【你的全部獎金】!$E$7:$E$26) -> 300 | H23: =SUMIF(【你的全部獎金】!$B$7:$B$26,$C23,【你的全部獎金】!$F$7:$F$26) -> 700 | I23: =SUMIF(【你的全部獎金】!$B$7:$B$26,$C23,【你的全部獎金】!$G$7:$G$26) -> 700 | J23: =SUMIF(【你的全部獎金】!$B$7:$B$26,$C23,【你的全部獎金】!$H$7:$H$26) -> 500 | K23: =SUM(H23,I23,J23)*30 -> 57000 | L23: =SUMIF(【你的全部獎金】!$B$7:$B$26,$C23,【你的全部獎金】!$I$7:$I$26) -> 0 | M23: =SUMIF(【你的全部獎金】!$B$7:$B$26,$C23,【你的全部獎金】!$J$7:$J$26) -> 0 | N23: =SUM(L23,M23)*10 -> 0 | O23: =SUM(F23,K23,N23) -> 93250 | P23: =O23/130000 -> 0.71730769 | Q23: =SUM(E23,G23,I23,J23,H23,L23) -> 3650 | R23: =REPT("█",MIN(20,INT(P23*2)))&REPT("░",20-MIN(20,INT(P23*2))) -> █░░░░░░░░░░░░░░░░░░░
B25: 合計 | E25: =SUM(E5:E23) -> 37100 | F25: =SUM(F5:F23) -> 927500 | G25: =SUM(G5:G23) -> 9000 | H25: =SUM(H5:H23) -> 19200 | K25: =SUM(K5:K23) -> 1368000 | L25: =SUM(L5:L23) -> 13375 | N25: =SUM(N5:N23) -> 143750 | O25: =SUM(O5:O23) -> 2439250 | Q25: =SUM(Q$5:Q$23) -> 105075

Sheet 2. 毛利分潤獎金
A1: 🏆 毛利分潤獎金
A2: 週期 | B2: 46264 | C2: =TODAY() -> 46291
A3: 店點 | B3: 姓名 | C3: 職級 | D3: 積分*20倍 | E3: 鼓勵獎金3,000元 | F3: 實際毛利 | G3: 預估月底毛利 | H3: 預估分潤獎金 | K3: 3階段高峰獎金
A4: 鼎山店 | B4: 劉家妘 | C4: 白金級 | D4: =H4*20 -> 310026.81 | E4: 100000 | F4: =SUMIF(數據!$A:$A,$B4,數據!$B:$B) -> 112520.11 | G4: =(F4/((DATEDIF($B$2,$C$2,"d")))*30) -> 125022.34 | H4: =IFERROR(IF(G4>=80000,G4*VLOOKUP(G4,$K$17:$P$29,IF(OR(C4="黃金級",C4="金級",C4="白金級"),2,IF(C4="銀級",4,IF(C4="銅級",5,IF(OR(C4="石頭",C4="石頭級"),6,0)))),TRUE()),0),0)+IF(G4>=E4,5000,0)+IF(G4>=120000,3000,0)+IF(G4>=140000,3000,0)+IF(G4>=160000,3000,0)+IF(G4>=180000,3000,0)+IF(G4>=200000,3000,0) -> 15501.341 | K4: 職級 | L4: 責任毛利 | M4: 鼓勵獎金 | N4: 12萬 | O4: 14萬 | P4: 20萬
A5: 鼎山店 | B5: 陳亭安 | C5: 銀級 | D5: =H5*20 -> 207489.3 | E5: 90000 | F5: =SUMIF(數據!$A:$A,$B5,數據!$B:$B) -> 107489.3 | G5: =(F5/((DATEDIF($B$2,$C$2,"d")))*30) -> 119432.56 | H5: =IFERROR(IF(G5>=80000,G5*VLOOKUP(G5,$K$17:$P$29,IF(OR(C5="黃金級",C5="金級",C5="白金級"),2,IF(C5="銀級",4,IF(C5="銅級",5,IF(OR(C5="石頭",C5="石頭級"),6,0)))),TRUE()),0),0)+IF(G5>=E5,5000,0)+IF(G5>=120000,3000,0)+IF(G5>=140000,3000,0)+IF(G5>=160000,3000,0)+IF(G5>=180000,3000,0)+IF(G5>=200000,3000,0) -> 10374.465 | K5: 黃金級 | L5: 100000 | M5: 5000 | N5: 3000 | O5: 3000 | P5: 3000
A6: 鼎山店 | B6: 高琦茗 | C6: 銅級 | D6: =H6*20 -> 0 | E6: 80000 | F6: =SUMIF(數據!$A:$A,$B6,數據!$B:$B) -> 63688.2 | G6: =(F6/((DATEDIF($B$2,$C$2,"d")))*30) -> 70764.667 | H6: =IFERROR(IF(G6>=80000,G6*VLOOKUP(G6,$K$17:$P$29,IF(OR(C6="黃金級",C6="金級",C6="白金級"),2,IF(C6="銀級",4,IF(C6="銅級",5,IF(OR(C6="石頭",C6="石頭級"),6,0)))),TRUE()),0),0)+IF(G6>=E6,5000,0)+IF(G6>=120000,3000,0)+IF(G6>=140000,3000,0)+IF(G6>=160000,3000,0)+IF(G6>=180000,3000,0)+IF(G6>=200000,3000,0) -> 0 | K6: 金級 | L6: 100000 | M6: 5000 | N6: 3000 | O6: 3000 | P6: 3000
A7: 鼎山店 | B7: 彥州 | C7: 石頭 | D7: =H7*20 -> 100000 | E7: 70000 | F7: =SUMIF(數據!$A:$A,$B7,數據!$B:$B) -> 66111.88 | G7: =(F7/((DATEDIF($B$2,$C$2,"d")))*30) -> 73457.644 | H7: =IFERROR(IF(G7>=80000,G7*VLOOKUP(G7,$K$17:$P$29,IF(OR(C7="黃金級",C7="金級",C7="白金級"),2,IF(C7="銀級",4,IF(C7="銅級",5,IF(OR(C7="石頭",C7="石頭級"),6,0)))),TRUE()),0),0)+IF(G7>=E7,5000,0)+IF(G7>=120000,3000,0)+IF(G7>=140000,3000,0)+IF(G7>=160000,3000,0)+IF(G7>=180000,3000,0)+IF(G7>=200000,3000,0) -> 5000 | K7: 白金級 | L7: 100000 | M7: 5000 | N7: 3000 | O7: 3000 | P7: 3000
A8: 總毛利 | B8: 姓名 | C8: 合計 | D8: =SUM(D4:D7) -> 617516.11 | E8: =SUM(E4:E7) -> 340000 | F8: =SUM(F4:F7) -> 349809.49 | G8: =SUM(G4:G7) -> 388677.21 | H8: =SUM(H4:H7) -> 30875.806 | K8: 銀級 | L8: 90000 | M8: 5000 | N8: 3000 | O8: 3000 | P8: 3000
A9: 陽明店 | B9: 劉芳廷 | C9: 銀級 | D9: =H9*20 -> 0 | E9: 90000 | F9: =SUMIF(數據!$A:$A,$B9,數據!$B:$B) -> 71824.6 | G9: =(F9/((DATEDIF($B$2,$C$2,"d")))*30) -> 79805.111 | H9: =IFERROR(IF(G9>=80000,G9*VLOOKUP(G9,$K$17:$P$29,IF(OR(C9="黃金級",C9="金級",C9="白金級"),2,IF(C9="銀級",4,IF(C9="銅級",5,IF(OR(C9="石頭",C9="石頭級"),6,0)))),TRUE()),0),0)+IF(G9>=E9,5000,0)+IF(G9>=120000,3000,0)+IF(G9>=140000,3000,0)+IF(G9>=160000,3000,0)+IF(G9>=180000,3000,0)+IF(G9>=200000,3000,0) -> 0 | K9: 銅級 | L9: 80000 | M9: 5000 | N9: 3000 | O9: 3000 | P9: 3000
A10: 陽明店 | B10: 邱雨蔚 | C10: 銀級 | D10: =H10*20 -> 418678.13 | E10: 90000 | F10: =SUMIF(數據!$A:$A,$B10,數據!$B:$B) -> 137546.4 | G10: =(F10/((DATEDIF($B$2,$C$2,"d")))*30) -> 152829.33 | H10: =IFERROR(IF(G10>=80000,G10*VLOOKUP(G10,$K$17:$P$29,IF(OR(C10="黃金級",C10="金級",C10="白金級"),2,IF(C10="銀級",4,IF(C10="銅級",5,IF(OR(C10="石頭",C10="石頭級"),6,0)))),TRUE()),0),0)+IF(G10>=E10,5000,0)+IF(G10>=120000,3000,0)+IF(G10>=140000,3000,0)+IF(G10>=160000,3000,0)+IF(G10>=180000,3000,0)+IF(G10>=200000,3000,0) -> 20933.907 | K10: 石頭級 | L10: 70000 | M10: 5000 | N10: 3000 | O10: 3000 | P10: 3000
A11: 陽明店 | B11: 林庭逸 | C11: 石頭 | D11: =H11*20 -> 138052.89 | E11: 70000 | F11: =SUMIF(數據!$A:$A,$B11,數據!$B:$B) -> 85619 | G11: =(F11/((DATEDIF($B$2,$C$2,"d")))*30) -> 95132.222 | H11: =IFERROR(IF(G11>=80000,G11*VLOOKUP(G11,$K$17:$P$29,IF(OR(C11="黃金級",C11="金級",C11="白金級"),2,IF(C11="銀級",4,IF(C11="銅級",5,IF(OR(C11="石頭",C11="石頭級"),6,0)))),TRUE()),0),0)+IF(G11>=E11,5000,0)+IF(G11>=120000,3000,0)+IF(G11>=140000,3000,0)+IF(G11>=160000,3000,0)+IF(G11>=180000,3000,0)+IF(G11>=200000,3000,0) -> 6902.6444 | K11: 小石頭 | L11: 60000 | M11: 5000 | N11: 3000 | O11: 3000 | P11: 3000
A13: 總毛利 | B13: 姓名 | C13: 合計 | D13: =SUM(D9:D11) -> 556731.02 | E13: =SUM(E9:E11) -> 250000 | F13: =SUM(F9:F12) -> 294990 | G13: =SUM(G9:G12) -> 327766.67 | H13: =SUM(H9:H12) -> 27836.551
A14: 後昌店 | B14: 郭家維 | C14: 銅級 | D14: =H14*20 -> 172127.61 | E14: 80000 | F14: =SUMIF(數據!$A:$A,$B14,數據!$B:$B) -> 92735.5 | G14: =(F14/((DATEDIF($B$2,$C$2,"d")))*30) -> 103039.44 | H14: =IFERROR(IF(G14>=80000,G14*VLOOKUP(G14,$K$17:$P$29,IF(OR(C14="黃金級",C14="金級",C14="白金級"),2,IF(C14="銀級",4,IF(C14="銅級",5,IF(OR(C14="石頭",C14="石頭級"),6,0)))),TRUE()),0),0)+IF(G14>=E14,5000,0)+IF(G14>=120000,3000,0)+IF(G14>=140000,3000,0)+IF(G14>=160000,3000,0)+IF(G14>=180000,3000,0)+IF(G14>=200000,3000,0) -> 8606.3806
A15: 後昌店 | B15: 黃閔聖 | C15: 銀級 | D15: =H15*20 -> 514400.29 | E15: 90000 | F15: =SUMIF(數據!$A:$A,$B15,數據!$B:$B) -> 150685.9 | G15: =(F15/((DATEDIF($B$2,$C$2,"d")))*30) -> 167428.78 | H15: =IFERROR(IF(G15>=80000,G15*VLOOKUP(G15,$K$17:$P$29,IF(OR(C15="黃金級",C15="金級",C15="白金級"),2,IF(C15="銀級",4,IF(C15="銅級",5,IF(OR(C15="石頭",C15="石頭級"),6,0)))),TRUE()),0),0)+IF(G15>=E15,5000,0)+IF(G15>=120000,3000,0)+IF(G15>=140000,3000,0)+IF(G15>=160000,3000,0)+IF(G15>=180000,3000,0)+IF(G15>=200000,3000,0) -> 25720.014 | K15: 倚盟各職級 毛利對照 抽成表
A16: 後昌店 | B16: 秦曼芯 | C16: 石頭 | D16: =H16*20 -> 0 | E16: 70000 | F16: =SUMIF(數據!$A:$A,$B16,數據!$B:$B) -> 49698 | G16: =(F16/((DATEDIF($B$2,$C$2,"d")))*30) -> 55220 | H16: =IFERROR(IF(G16>=80000,G16*VLOOKUP(G16,$K$17:$P$29,IF(OR(C16="黃金級",C16="金級",C16="白金級"),2,IF(C16="銀級",4,IF(C16="銅級",5,IF(OR(C16="石頭",C16="石頭級"),6,0)))),TRUE()),0),0)+IF(G16>=E16,5000,0)+IF(G16>=120000,3000,0)+IF(G16>=140000,3000,0)+IF(G16>=160000,3000,0)+IF(G16>=180000,3000,0)+IF(G16>=200000,3000,0) -> 0 | K16: 毛利門檻 | L16: 黃金級/金級/白金級 | N16: 銀級 | O16: 銅級 | P16: 石頭
K17: 80000 | L17: 0.04 | N17: 0.03 | O17: 0.025 | P17: 0.02
A18: 總毛利 | B18: 姓名 | C18: 合計 | D18: =SUM(D14:D16) -> 686527.9 | E18: =SUM(E14:E16) -> 240000 | F18: =SUM(F14:F17) -> 293119.4 | G18: =SUM(G14:G17) -> 325688.22 | H18: =SUM(H14:H17) -> 34326.395 | K18: 90000 | L18: 0.045 | N18: 0.035 | O18: 0.03 | P18: 0.02
A19: 仁雄店 | B19: 黃傑稜 | C19: 白金級 | D19: =H19*20 -> 469183.36 | E19: 100000 | F19: =SUMIF(數據!$A:$A,$B19,數據!$B:$B) -> 140165.64 | G19: =(F19/((DATEDIF($B$2,$C$2,"d")))*30) -> 155739.6 | H19: =IFERROR(IF(G19>=80000,G19*VLOOKUP(G19,$K$17:$P$29,IF(OR(C19="黃金級",C19="金級",C19="白金級"),2,IF(C19="銀級",4,IF(C19="銅級",5,IF(OR(C19="石頭",C19="石頭級"),6,0)))),TRUE()),0),0)+IF(G19>=E19,5000,0)+IF(G19>=120000,3000,0)+IF(G19>=140000,3000,0)+IF(G19>=160000,3000,0)+IF(G19>=180000,3000,0)+IF(G19>=200000,3000,0) -> 23459.168 | K19: 100000 | L19: 0.05 | N19: 0.04 | O19: 0.035 | P19: 0.03
A20: 仁雄店 | B20: 郭紳鴻 | C20: 銅級 | D20: =H20*20 -> 173393.79 | E20: 80000 | F20: =SUMIF(數據!$A:$A,$B20,數據!$B:$B) -> 94363.44 | G20: =(F20/((DATEDIF($B$2,$C$2,"d")))*30) -> 104848.27 | H20: =IFERROR(IF(G20>=80000,G20*VLOOKUP(G20,$K$17:$P$29,IF(OR(C20="黃金級",C20="金級",C20="白金級"),2,IF(C20="銀級",4,IF(C20="銅級",5,IF(OR(C20="石頭",C20="石頭級"),6,0)))),TRUE()),0),0)+IF(G20>=E20,5000,0)+IF(G20>=120000,3000,0)+IF(G20>=140000,3000,0)+IF(G20>=160000,3000,0)+IF(G20>=180000,3000,0)+IF(G20>=200000,3000,0) -> 8669.6893 | K20: 110000 | L20: 0.055 | N20: 0.045 | O20: 0.04 | P20: 0.035
A21: 仁雄店 | B21: 石佳穎 | C21: 銀級 | D21: =H21*20 -> 165752 | E21: 90000 | F21: =SUMIF(數據!$A:$A,$B21,數據!$B:$B) -> 84538.28 | G21: =(F21/((DATEDIF($B$2,$C$2,"d")))*30) -> 93931.422 | H21: =IFERROR(IF(G21>=80000,G21*VLOOKUP(G21,$K$17:$P$29,IF(OR(C21="黃金級",C21="金級",C21="白金級"),2,IF(C21="銀級",4,IF(C21="銅級",5,IF(OR(C21="石頭",C21="石頭級"),6,0)))),TRUE()),0),0)+IF(G21>=E21,5000,0)+IF(G21>=120000,3000,0)+IF(G21>=140000,3000,0)+IF(G21>=160000,3000,0)+IF(G21>=180000,3000,0)+IF(G21>=200000,3000,0) -> 8287.5998 | K21: 120000 | L21: 0.06 | N21: 0.05 | O21: 0.045 | P21: 0.04
A22: 仁雄店 | B22: 蔡冠廷 | C22: 石頭 | D22: =H22*20 -> 100000 | E22: 70000 | F22: =SUMIF(數據!$A:$A,$B22,數據!$B:$B) -> 65486.56 | G22: =(F22/((DATEDIF($B$2,$C$2,"d")))*30) -> 72762.844 | H22: =IFERROR(IF(G22>=80000,G22*VLOOKUP(G22,$K$17:$P$29,IF(OR(C22="黃金級",C22="金級",C22="白金級"),2,IF(C22="銀級",4,IF(C22="銅級",5,IF(OR(C22="石頭",C22="石頭級"),6,0)))),TRUE()),0),0)+IF(G22>=E22,5000,0)+IF(G22>=120000,3000,0)+IF(G22>=140000,3000,0)+IF(G22>=160000,3000,0)+IF(G22>=180000,3000,0)+IF(G22>=200000,3000,0) -> 5000 | K22: 130000 | L22: 0.07 | N22: 0.055 | O22: 0.05 | P22: 0.045
K23: 140000 | L23: 0.075 | N23: 0.06 | O23: 0.055 | P23: 0.05
A24: 總毛利 | B24: 姓名 | C24: 合計 | D24: =SUM(D19:D23) -> 908329.14 | E24: =SUM(E19:E23) -> 340000 | F24: =SUM(F19:F23) -> 384553.92 | G24: =SUM(G19:G23) -> 427282.13 | H24: =SUM(H19:H23) -> 45416.457 | K24: 150000 | L24: 0.08 | N24: 0.065 | O24: 0.06 | P24: 0.055
A25: 凱旋店 | B25: 陳宛姍 | C25: 白金級 | D25: =H25*20 -> 564809.65 | E25: 100000 | F25: =SUMIF(數據!$A:$A,$B25,數據!$B:$B) -> 150781.58 | G25: =(F25/((DATEDIF($B$2,$C$2,"d")))*30) -> 167535.09 | H25: =IFERROR(IF(G25>=80000,G25*VLOOKUP(G25,$K$17:$P$29,IF(OR(C25="黃金級",C25="金級",C25="白金級"),2,IF(C25="銀級",4,IF(C25="銅級",5,IF(OR(C25="石頭",C25="石頭級"),6,0)))),TRUE()),0),0)+IF(G25>=E25,5000,0)+IF(G25>=120000,3000,0)+IF(G25>=140000,3000,0)+IF(G25>=160000,3000,0)+IF(G25>=180000,3000,0)+IF(G25>=200000,3000,0) -> 28240.483 | K25: 160000 | L25: 0.085 | N25: 0.07 | O25: 0.065 | P25: 0.06
A26: 凱旋店 | B26: 黃子珊 | C26: 銀級 | D26: =H26*20 -> 200493.2 | E26: 90000 | F26: =SUMIF(數據!$A:$A,$B26,數據!$B:$B) -> 100493.2 | G26: =(F26/((DATEDIF($B$2,$C$2,"d")))*30) -> 111659.11 | H26: =IFERROR(IF(G26>=80000,G26*VLOOKUP(G26,$K$17:$P$29,IF(OR(C26="黃金級",C26="金級",C26="白金級"),2,IF(C26="銀級",4,IF(C26="銅級",5,IF(OR(C26="石頭",C26="石頭級"),6,0)))),TRUE()),0),0)+IF(G26>=E26,5000,0)+IF(G26>=120000,3000,0)+IF(G26>=140000,3000,0)+IF(G26>=160000,3000,0)+IF(G26>=180000,3000,0)+IF(G26>=200000,3000,0) -> 10024.66 | K26: 170000 | L26: 0.09 | N26: 0.075 | O26: 0.07 | P26: 0.065
A28: 凱旋店 | B28: 林瑞獻 | C28: 石頭 | D28: =H28*20 -> 132439.38 | E28: 70000 | F28: =SUMIF(數據!$A:$A,$B28,數據!$B:$B) -> 72988.6 | G28: =(F28/((DATEDIF($B$2,$C$2,"d")))*30) -> 81098.444 | H28: =IFERROR(IF(G28>=80000,G28*VLOOKUP(G28,$K$17:$P$29,IF(OR(C28="黃金級",C28="金級",C28="白金級"),2,IF(C28="銀級",4,IF(C28="銅級",5,IF(OR(C28="石頭",C28="石頭級"),6,0)))),TRUE()),0),0)+IF(G28>=E28,5000,0)+IF(G28>=120000,3000,0)+IF(G28>=140000,3000,0)+IF(G28>=160000,3000,0)+IF(G28>=180000,3000,0)+IF(G28>=200000,3000,0) -> 6621.9689 | K28: 190000 | L28: 0.1 | N28: 0.085 | O28: 0.08 | P28: 0.075
A29: 凱旋店 | B29: 劉宗翰 | C29: 小石頭 | D29: =H29*20 -> 0 | E29: 60000 | F29: =SUMIF(數據!$A:$A,$B29,數據!$B:$B) -> 52070.2 | G29: =(F29/((DATEDIF($B$2,$C$2,"d")))*30) -> 57855.778 | H29: =IFERROR(IF(G29>=80000,G29*VLOOKUP(G29,$K$17:$P$29,IF(OR(C29="黃金級",C29="金級",C29="白金級"),2,IF(C29="銀級",4,IF(C29="銅級",5,IF(OR(C29="石頭",C29="石頭級"),6,0)))),TRUE()),0),0)+IF(G29>=E29,5000,0)+IF(G29>=120000,3000,0)+IF(G29>=140000,3000,0)+IF(G29>=160000,3000,0)+IF(G29>=180000,3000,0)+IF(G29>=200000,3000,0) -> 0 | K29: 200000 | L29: 0.105 | N29: 0.09 | O29: 0.085 | P29: 0.08
A30: 總毛利 | C30: 合計 | D30: =SUM(D25:D29) -> 897742.23 | E30: =SUM(E25:E29) -> 320000 | F30: =SUM(F25:F29) -> 376333.58 | G30: =SUM(G25:G29) -> 418148.42 | H30: =SUM(H25:H29) -> 44887.111
A31: 區督導 | B31: 黃庭鈞 | C31: 黃金級 | D31: =H31*20 -> 558225.4 | E31: 100000 | F31: =SUMIF(數據!$A:$A,$B31,數據!$B:$B) -> 147295.8 | G31: =(F31/((DATEDIF($B$2,$C$2,"d")))*30) -> 163662 | H31: =IFERROR(IF(G31>=80000,G31*VLOOKUP(G31,$K$17:$P$29,IF(OR(C31="黃金級",C31="金級",C31="白金級"),2,IF(C31="銀級",4,IF(C31="銅級",5,IF(OR(C31="石頭",C31="石頭級"),6,0)))),TRUE()),0),0)+IF(G31>=E31,5000,0)+IF(G31>=120000,3000,0)+IF(G31>=140000,3000,0)+IF(G31>=160000,3000,0)+IF(G31>=180000,3000,0)+IF(G31>=200000,3000,0) -> 27911.27 | K31: 職 級 | L31: 職級責任目標 | M31: 鼓勵獎金 | N31: 毛利分潤方式
K32: 黃金級/金級/白金級 | L32: 100000 | M32: 5000 | N32: (A)達成職級責任目標 +$5,000 + X%分潤抽成 + 高峰獎金 3,000 + 顛峰獎金 3,000 + 聖母峰獎金 3,000
F33: 毛利合計 | G33: =SUM(F4,F5,F6,F7,F9,F10,F11,F14,F15,F16,F19,F20,F21,F22,F25,F26,F27,F28,F29,F31) -> 1846102.2 | K33: 銀級 | L33: 90000 | M33: 5000
F34: 預估月底毛利 | G34: =(G33/((DATEDIF($B$2,$C$2,"d")))*30) -> 2051224.7 | K34: 銅級 | L34: 80000 | M34: 5000 | N34: 舉例說明
K35: 石頭級 | L35: 80000 | M35: 5000 | N35: 銀級顧問 | O35: 銀級・月總毛利 $135,000 可拿到的分潤獎金 = 抽成 135,000×5.5% + 鼓勵 5,000 + 高峰 3,000 = 7,425 + 5,000 + 3,000 = $15,425

Sheet 🏆 追星獎
B1: 🏆 追星獎 月底彙整 — 星數與獎金自動加總
B2: 📅 在下方黃格填入【本月起訖日期】，所有人的總星數與追星獎金即自動更新。
B4: 📅 本月起訖 | D4: 月份起始 | E4: 46264 | F4: 月份結束 | G4: 46293 | H4: ← 每月改這兩格
M5: 線性推估
B6: 45–59★ → $3,000 | D6: 60–75★ → $5,500 | F6: 76★以上 → $8,000 | H6: 破紀錄>99★ → +$6,000
B8: 店點 | C8: 姓名 | D8: 職級 | E8: 台數 合計 | F8: 總星數 （自動） | G8: 預估獎金 | H8: 距下一檔 | I8: 進度
B9: 鼎山店 | C9: 劉家妘 | D9: 白金級 | E9: 23 | F9: 48 | G9: 3000 | H9: 差12星→$5500 | I9: ⬛⬛⬛▢▢
B10: 鼎山店 | C10: 陳亭安 | D10: 銀級 | E10: 25 | F10: 35 | G10: 0 | H10: 差10星→達底標 | I10: ▢▢▢▢▢
B11: 鼎山店 | C11: 高琦茗 | D11: 銅級 | E11: 18 | F11: 31 | G11: 0 | H11: 差14星→達底標 | I11: ▢▢▢▢▢
B12: 鼎山店 | C12: 彥州 | D12: 石頭 | E12: 17 | F12: 28 | G12: 0 | H12: 差17星→達底標 | I12: ▢▢▢▢▢
B13: 陽明店 | C13: 劉芳廷 | D13: 銀級 | E13: 19 | F13: 31 | G13: 0 | H13: 差14星→達底標 | I13: ▢▢▢▢▢
B14: 陽明店 | C14: 邱雨蔚 | D14: 銀級 | E14: 31 | F14: 52 | G14: 3000 | H14: 差8星→$5500 | I14: ⬛⬛⬛▢▢
B15: 陽明店 | C15: 林庭逸 | D15: 石頭 | E15: 18 | F15: 31 | G15: 0 | H15: 差14星→達底標 | I15: ▢▢▢▢▢
B16: 後昌店 | C16: 郭家維 | D16: 銅級 | E16: 21 | F16: 40 | G16: 0 | H16: 差5星→達底標 | I16: ▢▢▢▢▢
B17: 後昌店 | C17: 黃閔聖 | D17: 銀級 | E17: 40 | F17: 70 | G17: 8000 | H17: 差6星→$8000 | I17: ⬛⬛⬛⬛⬛
B18: 後昌店 | C18: 秦曼芯 | D18: 石頭 | E18: 15 | F18: 20 | G18: 0 | H18: 差25星→達底標 | I18: ▢▢▢▢▢
B19: 仁雄店 | C19: 黃傑稜 | D19: 金級 | E19: 39 | F19: 69 | G19: 8000 | H19: 差7星→$8000 | I19: ⬛⬛⬛⬛⬛
B20: 仁雄店 | C20: 郭紳鴻 | D20: 銅級 | E20: 19 | F20: 31 | G20: 0 | H20: 差14星→達底標 | I20: ▢▢▢▢▢
... B27: 區督導 | C27: 黃庭鈞 | D27: 黃金級 | E27: 30 | F27: 43 | G27: 3000 | H27: 差2星→達底標 | I27: ⬛⬛⬛▢▢
B28: 🏆 本月合計 | E28: =SUM(E9:E27) -> 459 | F28: =SUM(F9:F27) -> 769 | G28: =SUM(G9:G27) -> 34000
B30: ※ 8月新制 底標45星：未達不發、下月重新累積 ｜ 破紀錄>94★(單月實際)另加$6,000、同月僅最高一人 ｜ 財源為台哥大手機補貼，不影響公司23%毛利基準線 ｜ 一台5★機=5星

Sheet 3. 全壘打得分表
A1: 全壘打獎金進度追蹤系統 | AE1: 📅 動態預估參數
A2: 📊 即時追蹤全壘打獎金得分，不用等到月底才知道成績！ | AE2: 業績週期開始: | AF2: 46264
AE3: 今日日期: | AF3: =TODAY()-1 -> 46290
A4: 員工資訊 | D4: 總分與獎金 | F4: RT點數評分 (最高4分) | J4: RT件數評分 (最高4分) | N4: RT升轉 (2分) | Q4: RT1399 (2分) | T4: 特維 (2分) | W4: Device(3分) | Z4: 手機保險(3分) | AE4: 已過天數: | AF4: =TODAY()-$AF$2 -> 27
A5: 店點 | B5: 姓名 | C5: 職級 | D5: 月底 全壘打分數 | E5: 預估獎金 | F5: RT點數 目標 | G5: RT點數 實際 | H5: 達成率 | I5: 預估 得分 | J5: RT件數 目標 | K5: RT件數 實際 | L5: 達成率 | M5: 預估 得分 | N5: RT升轉 目標 | O5: RT升轉 實際 | P5: 預估 得分 | Q5: RT1399 目標 | R5: RT1399 實際 | S5: 預估 得分 | T5: 特維 目標 | U5: 特維 實際 | V5: 預估 得分 | W5: Device 目標 | X5: Device 實際 | Y5: 預估 得分 | Z5: 手機保險 目標 | AA5: 手機保險 實際 | AB5: 預估 得分 | AC5: 預估總分 | AE5: 總天數: | AF5: 30
A6: 鼎山店 | B6: 劉家妘 | C6: 白金級 | D6: =SUM(I6,M6,P6,S6,V6,Y6,AB6) -> 9.5491031 | E6: =IF(D6>=20,9000,IF(D6>=18,8000,IF(D6>=16,7000,IF(D6>=14,6000,IF(D6>=12,5000,IF(D6>=10,4000,IF(D6>=8,3000,0))))))) -> 3000 | F6: =SUMIF(■我的大類_重點目標!$C:$C,$B6,■我的大類_重點目標!$H:$H) -> 307 | G6: =SUMIF(數據!$A:$A,$B6,數據!$I:$I) -> 143.25 | H6: =IFERROR(G6/F6*($AF$5/$AF$4),0) -> 0.5184582 | I6: =MIN(H6,1)*4 -> 2.0738328 | J6: =SUMIF(■我的大類_重點目標!$C:$C,$B6,■我的大類_重點目標!$I:$I) -> 56 | K6: =SUMIF(數據!$A:$A,$B6,數據!$J:$J)+SUMIF(數據!$A:$A,$B6,數據!$K:$K) -> 22 | L6: =IFERROR(K6/J6*($AF$5/$AF$4),0) -> 0.43650794 | M6: =MIN(L6,1)*4 -> 1.7460317 | N6: =SUMIF(■我的大類_重點目標!$C:$C,$B6,■我的大類_重點目標!$J:$J) -> 21 | O6: =SUMIF(數據!$A:$A,$B6,數據!$L:$L)+SUMIF(數據!$A:$A,$B6,數據!$M:$M) -> 5 | P6: =MIN(IFERROR(O6/N6*($AF$5/$AF$4),0),1)*2 -> 0.52910053 | Q6: =SUMIF(■我的大類_重點目標!$C:$C,$B6,■我的大類_重點目標!$L:$L) -> 17 | R6: =SUMIF(數據!$A:$A,$B6,數據!$R:$R)+SUMIF(數據!$A:$A,$B6,數據!$S:$S) -> 7 | S6: =MIN(IFERROR(R6/Q6*($AF$5/$AF$4),0),1)*2 -> 0.91503268 | T6: =SUMIF(■我的大類_重點目標!$C:$C,$B6,■我的大類_重點目標!$M:$M) -> 17 | U6: =SUMIF(數據!$A:$A,$B6,數據!$N:$N)+SUMIF(數據!$A:$A,$B6,數據!$O:$O) -> 10 | V6: =MIN(IFERROR(U6/T6*($AF$5/$AF$4),0),1)*2 -> 1.3071895 | W6: =SUMIF(■我的大類_重點目標!$C:$C,$B6,■我的大類_重點目標!$N:$N) -> 46 | X6: =SUMIF(數據!$A:$A,$B6,數據!$V:$V)+SUMIF(數據!$A:$A,$B6,數據!$W:$W) -> 17 | Y6: =MIN(IFERROR(X6/W6*($AF$5/$AF$4),0),1)*3 -> 1.2318841 | Z6: =SUMIF(■我的大類_重點目標!$C:$C,$B6,■我的大類_重點目標!$O:$O) -> 21 | AA6: =SUMIF(數據!$A:$A,$B6,數據!$X:$X)+SUMIF(數據!$A:$A,$B6,數據!$Y:$Y) -> 11 | AB6: =MIN(IFERROR(AA6/Z6*($AF$5/$AF$4),0),1)*3 -> 1.7460317 | AC6: =SUM(I6,M6,P6,S6,V6,Y6,AB6) -> 9.5491031 | AE6: 20 | AF6: 🏆全壘打 | AG6: 9000
A7: 鼎山店 | B7: 陳亭安 | C7: 銀級 | D7: =SUM(I7,M7,P7,S7,V7,Y7,AB7) -> 13.559183 | E7: =IF(D7>=20,9000,IF(D7>=18,8000,IF(D7>=16,7000,IF(D7>=14,6000,IF(D7>=12,5000,IF(D7>=10,4000,IF(D7>=8,3000,0))))))) -> 5000 | F7: =SUMIF(■我的大類_重點目標!$C:$C,$B7,■我的大類_重點目標!$H:$H) -> 288 | G7: =SUMIF(數據!$A:$A,$B7,數據!$I:$I) -> 216 | H7: =IFERROR(G7/F7*($AF$5/$AF$4),0) -> 0.83333333 | I7: =MIN(H7,1)*4 -> 3.3333333 | J7: =SUMIF(■我的大類_重點目標!$C:$C,$B7,■我的大類_重點目標!$I:$I) -> 52 | K7: =SUMIF(數據!$A:$A,$B7,數據!$J:$J)+SUMIF(數據!$A:$A,$B7,數據!$K:$K) -> 28 | L7: =IFERROR(K7/J7*($AF$5/$AF$4),0) -> 0.5982906 | M7: =MIN(L7,1)*4 -> 2.3931624 | N7: =SUMIF(■我的大類_重點目標!$C:$C,$B7,■我的大類_重點目標!$J:$J) -> 20 | O7: =SUMIF(數據!$A:$A,$B7,數據!$L:$L)+SUMIF(數據!$A:$A,$B7,數據!$M:$M) -> 11 | P7: =MIN(IFERROR(O7/N7*($AF$5/$AF$4),0),1)*2 -> 1.2222222 | Q7: =SUMIF(■我的大類_重點目標!$C:$C,$B7,■我的大類_重點目標!$L:$L) -> 15 | R7: =SUMIF(數據!$A:$A,$B7,數據!$R:$R)+SUMIF(數據!$A:$A,$B7,數據!$S:$S) -> 11 | S7: =MIN(IFERROR(R7/Q7*($AF$5/$AF$4),0),1)*2 -> 1.6296296 | T7: =SUMIF(■我的大類_重點目標!$C:$C,$B7,■我的大類_重點目標!$M:$M) -> 15 | U7: =SUMIF(數據!$A:$A,$B7,數據!$N:$N)+SUMIF(數據!$A:$A,$B7,數據!$O:$O) -> 7 | V7: =MIN(IFERROR(U7/T7*($AF$5/$AF$4),0),1)*2 -> 1.037037 | W7: =SUMIF(■我的大類_重點目標!$C:$C,$B7,■我的大類_重點目標!$N:$N) -> 43 | X7: =SUMIF(數據!$A:$A,$B7,數據!$V:$V)+SUMIF(數據!$A:$A,$B7,數據!$W:$W) -> 24 | Y7: =MIN(IFERROR(X7/W7*($AF$5/$AF$4),0),1)*3 -> 1.8604651 | Z7: =SUMIF(■我的大類_重點目標!$C:$C,$B7,■我的大類_重點目標!$O:$O) -> 20 | AA7: =SUMIF(數據!$A:$A,$B7,數據!$X:$X)+SUMIF(數據!$A:$A,$B7,數據!$Y:$Y) -> 12.5 | AB7: =MIN(IFERROR(AA7/Z7*($AF$5/$AF$4),0),1)*3 -> 2.0833333 | AC7: =SUM(I7,M7,P7,S7,V7,Y7,AB7) -> 13.559183 | AE7: 19 | AF7: 超級明星 | AG7: 8000
A8: 鼎山店 | B8: 高琦茗 | C8: 銅級 | D8: =SUM(I8,M8,P8,S8,V8,Y8,AB8) -> 9.0059215 | E8: =IF(D8>=20,9000,IF(D8>=18,8000,IF(D8>=16,7000,IF(D8>=14,6000,IF(D8>=12,5000,IF(D8>=10,4000,IF(D8>=8,3000,0))))))) -> 3000 | F8: =SUMIF(■我的大類_重點目標!$C:$C,$B8,■我的大類_重點目標!$H:$H) -> 269 | G8: =SUMIF(數據!$A:$A,$B8,數據!$I:$I) -> 113.45 | H8: =IFERROR(G8/F8*($AF$5/$AF$4),0) -> 0.46860801 | I8: =MIN(H8,1)*4 -> 1.8744321 | J8: =SUMIF(■我的大類_重點目標!$C:$C,$B8,■我的大類_重點目標!$I:$I) -> 49 | K8: =SUMIF(數據!$A:$A,$B8,數據!$J:$J)+SUMIF(數據!$A:$A,$B8,數據!$K:$K) -> 16 | L8: =IFERROR(K8/J8*($AF$5/$AF$4),0) -> 0.36281179 | M8: =MIN(L8,1)*4 -> 1.4512472 | N8: =SUMIF(■我的大類_重點目標!$C:$C,$B8,■我的大類_重點目標!$J:$J) -> 19 | O8: =SUMIF(數據!$A:$A,$B8,數據!$L:$L)+SUMIF(數據!$A:$A,$B8,數據!$M:$M) -> 9 | P8: =MIN(IFERROR(O8/N8*($AF$5/$AF$4),0),1)*2 -> 1.0526316 | Q8: =SUMIF(■我的大類_重點目標!$C:$C,$B8,■我的大類_重點目標!$L:$L) -> 14 | R8: =SUMIF(數據!$A:$A,$B8,數據!$R:$R)+SUMIF(數據!$A:$A,$B8,數據!$S:$S) -> 4 | S8: =MIN(IFERROR(R8/Q8*($AF$5/$AF$4),0),1)*2 -> 0.63492063 | T8: =SUMIF(■我的大類_重點目標!$C:$C,$B8,■我的大類_重點目標!$M:$M) -> 14 | U8: =SUMIF(數據!$A:$A,$B8,數據!$N:$N)+SUMIF(數據!$A:$A,$B8,數據!$O:$O) -> 7 | V8: =MIN(IFERROR(U8/T8*($AF$5/$AF$4),0),1)*2 -> 1.1111111 | W8: =SUMIF(■我的大類_重點目標!$C:$C,$B8,■我的大類_重點目標!$N:$N) -> 40 | X8: =SUMIF(數據!$A:$A,$B8,數據!$V:$V)+SUMIF(數據!$A:$A,$B8,數據!$W:$W) -> 13 | Y8: =MIN(IFERROR(X8/W8*($AF$5/$AF$4),0),1)*3 -> 1.0833333 | Z8: =SUMIF(■我的大類_重點目標!$C:$C,$B8,■我的大類_重點目標!$O:$O) -> 19 | AA8: =SUMIF(數據!$A:$A,$B8,數據!$X:$X)+SUMIF(數據!$A:$A,$B8,數據!$Y:$Y) -> 10.25 | AB8: =MIN(IFERROR(AA8/Z8*($AF$5/$AF$4),0),1)*3 -> 1.7982456 | AC8: =SUM(I8,M8,P8,S8,V8,Y8,AB8) -> 9.0059215 | AE8: 18 | AF8: 超級明星 | AG8: 8000
